Workbook

Sheet GLOBALIZADA COPASA
C2: SECRETARIA DE ESTADO DE JUSTIÇA E SEGURANÇA PÚBLICA - CNPJ: 05.487.631/0001-09 | P2: DEZEMBRO | X2: JANEIRO | AI2: FEVEREIRO | AT2: MARÇO | BE2: ABRIL | BP2: MAIO | CA2: JUNHO | CL2: JULHO | CW2: AGOSTO | DH2: SETEMBRO | DS2: OUTUBRO | ED2: NOVEMBRO | EO2: DEZEMBRO
C4: UNIDADES PRISIONAIS | D4: UNIDADE EXECUTORA | E4: UPG | F4: HIDRÔMETRO | G4: MATRÍCULA | H4: CONCESSIONÁRIA | I4: CNPJ | J4: IDENTIFICADOR (1) | K4: IDENTIFICADOR (2) | L4: EMPENHO (FONTE 10) | M4: EMPENHO DE ENCARGOS (FONTE 10) | N4: EMPENHO (FONTE 60) | O4: EMPENHO DE ENCARGOS (FONTE 60) | P4: IR (12) | Q4: ENCARGOS (12) | R4: LÍQUIDO (12) | S4: M³ (12) | T4: Nº SEI | U4: VENCIMENTO | V4: Variação Consumo | W4: Variação Financeiro | X4: BRUTO (1) | Y4: IR (1) | Z4: ENCARGOS (1) | AA4: LÍQUIDO (1) | AB4: M³ (1) | AC4: VENCIMENTO (1) | AD4: Nº SEI (1) | AE4: ENVIADO AO DED (1) | AF4: PAGO (1) | AG4: Variação Consumo (1) | AH4: Variação Financeiro (1) | AI4: BRUTO (2) | AJ4: IR (2) | AK4: ENCARGOS (2) | AL4: LÍQUIDO (1)2 | AM4: M³ (2) | AN4: VENCIMENTO (2) | AO4: Nº SEI (2) | AP4: ENVIADO AO DED (1)2 | AQ4: PAGO (1)3 | AR4: Variação Consumo (2) | AS4: Variação Financeiro (2) | AT4: BRUTO (3) | AU4: IR (3)3 | AV4: ENCARGOS (3) | AW4: LÍQUIDO (3) | AX4: M³ (3) | AY4: VENCIMENTO (3) | AZ4: Nº SEI (3) | BA4: ENVIADO AO DED (1)3 | BB4: PAGO (1)4 | BC4: Variação Consumo (3) | BD4: Variação Financeiro (3) | BE4: BRUTO (4) | BF4: IR (4) | BG4: ENCARGOS (4) | BH4: LÍQUIDO (4) | BI4: M³ (4) | BJ4: VENCIMENTO (4) | BK4: Nº SEI (4) | BL4: ENVIADO AO DED (1)22 | BM4: PAGO (1)33 | BN4: Variação Consumo (4) | BO4: Variação Financeiro (4) | BP4: BRUTO (3)2 | BQ4: IR (3)33 | BR4: ENCARGOS (3)4 | BS4: LÍQUIDO (3)5 | BT4: M³ (3)6 | BU4: VENCIMENTO (3)7 | BV4: Nº SEI (3)8 | BW4: ENVIADO AO DED (1)39 | BX4: PAGO (1)410 | BY4: Variação Consumo (3)11 | BZ4: Variação Financeiro (3)12 | CA4: BRUTO (4)13 | CB4: IR (4)14 | CC4: ENCARGOS (4)15 | CD4: LÍQUIDO (4)16 | CE4: M³ (4)17 | CF4: VENCIMENTO (4)18 | CG4: Nº SEI (4)19 | CH4: ENVIADO AO DED (1)2220 | CI4: PAGO (1)3321 | CJ4: Variação Consumo (4)22 | CK4: Variação Financeiro (4)23 | CL4: BRUTO (3)3 | CM4: IR (3)34 | CN4: ENCARGOS (3)5 | CO4: LÍQUIDO (3)6 | CP4: M³ (3)7 | CQ4: VENCIMENTO (3)8 | CR4: Nº SEI (3)9 | CS4: ENVIADO AO DED (1)310 | CT4: PAGO (1)411 | CU4: Variação Consumo (3)12 | CV4: Variação Financeiro (3)13 | CW4: BRUTO (4)14 | CX4: IR (4)15 | CY4: ENCARGOS (4)16 | CZ4: LÍQUIDO (4)17 | DA4: M³ (4)18 | DB4: VENCIMENTO (4)19 | DC4: Nº SEI (4)20 | DD4: ENVIADO AO DED (1)2221 | DE4: PAGO (1)3322 | DF4: Variação Consumo (4)23 | DG4: Variação Financeiro (4)24 | DH4: BRUTO (3)32 | DI4: IR (3)343 | DJ4: ENCARGOS (3)54 | DK4: LÍQUIDO (3)65 | DL4: M³ (3)76 | DM4: VENCIMENTO (3)87 | DN4: Nº SEI (3)98 | DO4: ENVIADO AO DED (1)3109 | DP4: PAGO (1)41110 | DQ4: Variação Consumo (3)1211 | DR4: Variação Financeiro (3)1312 | DS4: BRUTO (4)1413 | DT4: IR (4)1514 | DU4: ENCARGOS (4)1615 | DV4: LÍQUIDO (4)1716 | DW4: M³ (4)1817 | DX4: VENCIMENTO (4)1918 | DY4: Nº SEI (4)2019 | DZ4: ENVIADO AO DED (1)222120 | EA4: PAGO (1)332221 | EB4: Variação Consumo (4)2322 | EC4: Variação Financeiro (4)2423 | ED4: BRUTO (3)322 | EE4: IR (3)3433 | EF4: ENCARGOS (3)544 | EG4: LÍQUIDO (3)655 | EH4: M³ (3)766 | EI4: VENCIMENTO (3)877 | EJ4: Nº SEI (3)988 | EK4: ENVIADO AO DED (1)31099 | EL4: PAGO (1)4111010 | EM4: Variação Consumo (3)121111 | EN4: Variação Financeiro (3)131212 | EO4: BRUTO (4)141313 | EP4: IR (4)151414 | EQ4: ENCARGOS (4)161515 | ER4: LÍQUIDO (4)171616 | ES4: M³ (4)181717 | ET4: VENCIMENTO (4)191818 | EU4: Nº SEI (4)201919 | EV4: ENVIADO AO DED (1)22212020 | EW4: PAGO (1)33222121 | EX4: Variação Consumo (4)232222 | EY4: Variação Financeiro (4)242323
C5: 3ª AISP ED. JK (BH) | D5: 1450022 | E5: 184 | F5: A24H0000770 | G5: 00013610520 | H5: COMPANHIA DE SANEAMENTO DE MINAS GERAIS COPASA MG | I5: 17.281.106/0001-03 | N5: 107 | P5: 73.12 | R5: 1450.23 | S5: 70 | T5: 1450.01.0005511/2026-51 | X5: =AA5 + ABS(Y5) + ABS(Z5) -> 1701.94 | Y5: -81.69 | Z5: 0 | AA5: 1620.25 | AB5: 76 | AC5: 10/03/2026 | AD5: 1450.01.0029372/2026-78 | AE5: TRUE | AF5: TRUE | AG5: =(AB5-S5)/S5 -> 0.085714286 | AH5: =(AA5-R5)/R5 -> 0.11723658 | AI5: =AL5 + ABS(AJ5) + ABS(AK5) -> 2281.33 | AJ5: -109.5 | AK5: 0 | AL5: 2171.83 | AM5: 95 | AN5: 46122 | AO5: 1450.01.0046622/2026-25 | AP5: TRUE | AQ5: TRUE | AR5: =(AM5-AB5)/AB5 -> 0.25 | AS5: =(AL5-AA5)/AA5 -> 0.34042895 | AT5: =AW5 + ABS(AU5) + ABS(AV5) -> 0 | BA5: FALSE | BB5: FALSE | BC5: =(AX5-AM5)/AM5 -> -1 | BD5: =(AW5-AL5)/AL5 -> -1 | BE5: =BH5 + ABS(BF5) + ABS(BG5) -> 0 | BL5: FALSE | BM5: FALSE | BN5: =(BI5-AZ5)/AZ5 -> #DIV/0! | BO5: =(BH5-AW5)/AW5 -> #DIV/0! | BP5: =BS5 + ABS(BQ5) + ABS(BR5) -> 0 | BW5: FALSE | BX5: FALSE | BY5: =(BT5-BI5)/BI5 -> #DIV/0! | BZ5: =(BS5-BH5)/BH5 -> #DIV/0! | CA5: =CD5 + ABS(CB5) + ABS(CC5) -> 0 | CH5: FALSE | CI5: FALSE | CJ5: =(CE5-BV5)/BV5 -> #DIV/0! | CK5: =(CD5-BS5)/BS5 -> #DIV/0! | CL5: =CO5 + ABS(CM5) + ABS(CN5) -> 0 | CS5: FALSE | CT5: FALSE | CU5: =(CP5-CE5)/CE5 -> #DIV/0! | CV5: =(CO5-CD5)/CD5 -> #DIV/0! | CW5: =CZ5 + ABS(CX5) + ABS(CY5) -> 0 | DD5: FALSE | DE5: FALSE | DF5: =(DA5-CR5)/CR5 -> #DIV/0! | DG5: =(CZ5-CO5)/CO5 -> #DIV/0! | DH5: =DK5 + ABS(DI5) + ABS(DJ5) -> 0 | DO5: FALSE | DP5: FALSE | DQ5: =(DL5-DA5)/DA5 -> #DIV/0! | DR5: =(DK5-CZ5)/CZ5 -> #DIV/0! | DS5: =DV5 + ABS(DT5) + ABS(DU5) -> 0 | DZ5: FALSE | EA5: FALSE | EB5: =(DW5-DN5)/DN5 -> #DIV/0! | EC5: =(DV5-DK5)/DK5 -> #DIV/0! | ED5: =EG5 + ABS(EE5) + ABS(EF5) -> 0 | EK5: FALSE | EL5: FALSE | EM5: =(EH5-DW5)/DW5 -> #DIV/0! | EN5: =(EG5-DV5)/DV5 -> #DIV/0! | EO5: =ER5 + ABS(EP5) + ABS(EQ5) -> 0 | EV5: FALSE | EW5: FALSE | EX5: =(ES5-EJ5)/EJ5 -> #DIV/0! | EY5: =(ER5-EG5)/EG5 -> #DIV/0!
C6: 12ª RISP (DRAP IPATINGA) | D6: 1450022 | E6: 198 | F6: Y19G0986114 | G6: 00115043942 | H6: COMPANHIA DE SANEAMENTO DE MINAS GERAIS COPASA MG | I6: 17.281.106/0001-03 | N6: 107 | P6: 15.69 | R6: 311.2 | S6: 20 | T6: 1450.01.0005511/2026-51 | X6: =AA6 + ABS(Y6) + ABS(Z6) -> 208.97 | Y6: -10.03 | Z6: 0 | AA6: 198.94 | AB6: 13 | AC6: 10/03/2026 | AD6: 1450.01.0029372/2026-78 | AE6: TRUE | AF6: TRUE | AG6: =(AB6-S6)/S6 -> -0.35 | AH6: =(AA6-R6)/R6 -> -0.36073265 | AI6: =AL6 + ABS(AJ6) + ABS(AK6) -> 259.04 | AJ6: -12.43 | AK6: 0 | AL6: 246.61 | AM6: 15 | AN6: 46122 | AO6: 1450.01.0046622/2026-25 | AP6: TRUE | AQ6: TRUE | AR6: =(AM6-AB6)/AB6 -> 0.15384615 | AS6: =(AL6-AA6)/AA6 -> 0.23961999 | AT6: =AW6 + ABS(AU6) + ABS(AV6) -> 0 | BA6: FALSE | BB6: FALSE | BC6: =(AX6-AM6)/AM6 -> -1 | BD6: =(AW6-AL6)/AL6 -> -1 | BE6: =BH6 + ABS(BF6) + ABS(BG6) -> 0 | BL6: FALSE | BM6: FALSE | BN6: =(BI6-AZ6)/AZ6 -> #DIV/0! | BO6: =(BH6-AW6)/AW6 -> #DIV/0! | BP6: =BS6 + ABS(BQ6) + ABS(BR6) -> 0 | BW6: FALSE | BX6: FALSE | BY6: =(BT6-BI6)/BI6 -> #DIV/0! | BZ6: =(BS6-BH6)/BH6 -> #DIV/0! | CA6: =CD6 + ABS(CB6) + ABS(CC6) -> 0 | CH6: FALSE | CI6: FALSE | CJ6: =(CE6-BV6)/BV6 -> #DIV/0! | CK6: =(CD6-BS6)/BS6 -> #DIV/0! | CL6: =CO6 + ABS(CM6) + ABS(CN6) -> 0 | CS6: FALSE | CT6: FALSE | CU6: =(CP6-CE6)/CE6 -> #DIV/0! | CV6: =(CO6-CD6)/CD6 -> #DIV/0! | CW6: =CZ6 + ABS(CX6) + ABS(CY6) -> 0 | DD6: FALSE | DE6: FALSE | DF6: =(DA6-CR6)/CR6 -> #DIV/0! | DG6: =(CZ6-CO6)/CO6 -> #DIV/0! | DH6: =DK6 + ABS(DI6) + ABS(DJ6) -> 0 | DO6: FALSE | DP6: FALSE | DQ6: =(DL6-DA6)/DA6 -> #DIV/0! | DR6: =(DK6-CZ6)/CZ6 -> #DIV/0! | DS6: =DV6 + ABS(DT6) + ABS(DU6) -> 0 | DZ6: FALSE | EA6: FALSE | EB6: =(DW6-DN6)/DN6 -> #DIV/0! | EC6: =(DV6-DK6)/DK6 -> #DIV/0! | ED6: =EG6 + ABS(EE6) + ABS(EF6) -> 0 | EK6: FALSE | EL6: FALSE | EM6: =(EH6-DW6)/DW6 -> #DIV/0! | EN6: =(EG6-DV6)/DV6 -> #DIV/0! | EO6: =ER6 + ABS(EP6) + ABS(EQ6) -> 0 | EV6: FALSE | EW6: FALSE | EX6: =(ES6-EJ6)/EJ6 -> #DIV/0! | EY6: =(ER6-EG6)/EG6 -> #DIV/0!
C7: 13ª RISP (BARBACENA) | D7: 1450022 | E7: 259 | F7: Y21G1271058 | G7: 00164218301 | H7: COMPANHIA DE SANEAMENTO DE MINAS GERAIS COPASA MG | I7: 17.281.106/0001-03 | N7: 107 | P7: 1.72 | R7: 34.18 | S7: 1 | T7: 1450.01.0005511/2026-51 | X7: =AA7 + ABS(Y7) + ABS(Z7) -> 35.9 | Y7: -1.72 | Z7: 0 | AA7: 34.18 | AB7: 1 | AC7: 10/03/2026 | AD7: 1450.01.0029372/2026-78 | AE7: TRUE | AF7: TRUE | AG7: =(AB7-S7)/S7 -> 0 | AH7: =(AA7-R7)/R7 -> 0 | AI7: =AL7 + ABS(AJ7) + ABS(AK7) -> 36.25 | AJ7: -1.74 | AK7: 0 | AL7: 34.51 | AM7: 0 | AN7: 46122 | AO7: 1450.01.0046622/2026-25 | AP7: TRUE | AQ7: TRUE | AR7: =(AM7-AB7)/AB7 -> -1 | AS7: =(AL7-AA7)/AA7 -> 0.0096547689 | AT7: =AW7 + ABS(AU7) + ABS(AV7) -> 0 | BA7: FALSE | BB7: FALSE | BC7: =(AX7-AM7)/AM7 -> #DIV/0! | BD7: =(AW7-AL7)/AL7 -> -1 | BE7: =BH7 + ABS(BF7) + ABS(BG7) -> 0 | BL7: FALSE | BM7: FALSE | BN7: =(BI7-AZ7)/AZ7 -> #DIV/0! | BO7: =(BH7-AW7)/AW7 -> #DIV/0! | BP7: =BS7 + ABS(BQ7) + ABS(BR7) -> 0 | BW7: FALSE | BX7: FALSE | BY7: =(BT7-BI7)/BI7 -> #DIV/0! | BZ7: =(BS7-BH7)/BH7 -> #DIV/0! | CA7: =CD7 + ABS(CB7) + ABS(CC7) -> 0 | CH7: FALSE | CI7: FALSE | CJ7: =(CE7-BV7)/BV7 -> #DIV/0! | CK7: =(CD7-BS7)/BS7 -> #DIV/0! | CL7: =CO7 + ABS(CM7) + ABS(CN7) -> 0 | CS7: FALSE | CT7: FALSE | CU7: =(CP7-CE7)/CE7 -> #DIV/0! | CV7: =(CO7-CD7)/CD7 -> #DIV/0! | CW7: =CZ7 + ABS(CX7) + ABS(CY7) -> 0 | DD7: FALSE | DE7: FALSE | DF7: =(DA7-CR7)/CR7 -> #DIV/0! | DG7: =(CZ7-CO7)/CO7 -> #DIV/0! | DH7: =DK7 + ABS(DI7) + ABS(DJ7) -> 0 | DO7: FALSE | DP7: FALSE | DQ7: =(DL7-DA7)/DA7 -> #DIV/0! | DR7: =(DK7-CZ7)/CZ7 -> #DIV/0! | DS7: =DV7 + ABS(DT7) + ABS(DU7) -> 0 | DZ7: FALSE | EA7: FALSE | EB7: =(DW7-DN7)/DN7 -> #DIV/0! | EC7: =(DV7-DK7)/DK7 -> #DIV/0! | ED7: =EG7 + ABS(EE7) + ABS(EF7) -> 0 | EK7: FALSE | EL7: FALSE | EM7: =(EH7-DW7)/DW7 -> #DIV/0! | EN7: =(EG7-DV7)/DV7 -> #DIV/0! | EO7: =ER7 + ABS(EP7) + ABS(EQ7) -> 0 | EV7: FALSE | EW7: FALSE | EX7: =(ES7-EJ7)/EJ7 -> #DIV/0! | EY7: =(ER7-EG7)/EG7 -> #DIV/0!
C8: 17ª RISP (POUSO ALEGRE) | D8: 1450022 | E8: 263 | F8: Y24S0064490 | G8: 00024659207 | H8: COMPANHIA DE SANEAMENTO DE MINAS GERAIS COPASA MG | I8: 17.281.106/0001-03 | N8: 107 | P8: 33.01 | R8: 654.76 | S8: 37 | T8: 1450.01.0005511/2026-51 | X8: =AA8 + ABS(Y8) + ABS(Z8) -> 87.48 | Y8: -4.2 | Z8: 0 | AA8: 83.28 | AB8: 4 | AC8: 10/03/2026 | AD8: 1450.01.0029372/2026-78 | AE8: TRUE | AF8: TRUE | AG8: =(AB8-S8)/S8 -> -0.89189189 | AH8: =(AA8-R8)/R8 -> -0.87280836 | AI8: =AL8 + ABS(AJ8) + ABS(AK8) -> 113.88 | AJ8: -5.47 | AK8: 0 | AL8: 108.41 | AM8: 6 | AN8: 46122 | AO8: 1450.01.0046622/2026-25 | AP8: TRUE | AQ8: TRUE | AR8: =(AM8-AB8)/AB8 -> 0.5 | AS8: =(AL8-AA8)/AA8 -> 0.30175312 | AT8: =AW8 + ABS(AU8) + ABS(AV8) -> 0 | BA8: FALSE | BB8: FALSE | BC8: =(AX8-AM8)/AM8 -> -1 | BD8: =(AW8-AL8)/AL8 -> -1 | BE8: =BH8 + ABS(BF8) + ABS(BG8) -> 0 | BL8: FALSE | BM8: FALSE | BN8: =(BI8-AZ8)/AZ8 -> #DIV/0! | BO8: =(BH8-AW8)/AW8 -> #DIV/0! | BP8: =BS8 + ABS(BQ8) + ABS(BR8) -> 0 | BW8: FALSE | BX8: FALSE | BY8: =(BT8-BI8)/BI8 -> #DIV/0! | BZ8: =(BS8-BH8)/BH8 -> #DIV/0! | CA8: =CD8 + ABS(CB8) + ABS(CC8) -> 0 | CH8: FALSE | CI8: FALSE | CJ8: =(CE8-BV8)/BV8 -> #DIV/0! | CK8: =(CD8-BS8)/BS8 -> #DIV/0! | CL8: =CO8 + ABS(CM8) + ABS(CN8) -> 0 | CS8: FALSE | CT8: FALSE | CU8: =(CP8-CE8)/CE8 -> #DIV/0! | CV8: =(CO8-CD8)/CD8 -> #DIV/0! | CW8: =CZ8 + ABS(CX8) + ABS(CY8) -> 0 | DD8: FALSE | DE8: FALSE | DF8: =(DA8-CR8)/CR8 -> #DIV/0! | DG8: =(CZ8-CO8)/CO8 -> #DIV/0! | DH8: =DK8 + ABS(DI8) + ABS(DJ8) -> 0 | DO8: FALSE | DP8: FALSE | DQ8: =(DL8-DA8)/DA8 -> #DIV/0! | DR8: =(DK8-CZ8)/CZ8 -> #DIV/0! | DS8: =DV8 + ABS(DT8) + ABS(DU8) -> 0 | DZ8: FALSE | EA8: FALSE | EB8: =(DW8-DN8)/DN8 -> #DIV/0! | EC8: =(DV8-DK8)/DK8 -> #DIV/0! | ED8: =EG8 + ABS(EE8) + ABS(EF8) -> 0 | EK8: FALSE | EL8: FALSE | EM8: =(EH8-DW8)/DW8 -> #DIV/0! | EN8: =(EG8-DV8)/DV8 -> #DIV/0! | EO8: =ER8 + ABS(EP8) + ABS(EQ8) -> 0 | EV8: FALSE | EW8: FALSE | EX8: =(ES8-EJ8)/EJ8 -> #DIV/0! | EY8: =(ER8-EG8)/EG8 -> #DIV/0!
C9: 17ª RISP (POUSO ALEGRE) | D9: 1450022 | E9: 263 | F9: Y22G1372195 | G9: 00024659185 | H9: COMPANHIA DE SANEAMENTO DE MINAS GERAIS COPASA MG | I9: 17.281.106/0001-03 | N9: 107 | P9: 2.6 | R9: 51.52 | T9: 1450.01.0005511/2026-51 | X9: =AA9 + ABS(Y9) + ABS(Z9) -> 54.12 | Y9: -2.6 | Z9: 0 | AA9: 51.52 | AB9: 0 | AC9: 10/03/2026 | AD9: 1450.01.0029372/2026-78 | AE9: TRUE | AF9: TRUE | AG9: 0 | AH9: =(AA9-R9)/R9 -> 0 | AI9: =AL9 + ABS(AJ9) + ABS(AK9) -> 58.28 | AJ9: -2.8 | AK9: 0 | AL9: 55.48 | AM9: 0 | AN9: 46122 | AO9: 1450.01.0046622/2026-25 | AP9: TRUE | AQ9: TRUE | AR9: 0 | AS9: =(AL9-AA9)/AA9 -> 0.076863354 | AT9: =AW9 + ABS(AU9) + ABS(AV9) -> 0 | BA9: FALSE | BB9: FALSE | BC9: =(AX9-AM9)/AM9 -> #DIV/0! | BD9: =(AW9-AL9)/AL9 -> -1 | BE9: =BH9 + ABS(BF9) + ABS(BG9) -> 0 | BL9: FALSE | BM9: FALSE | BN9: =(BI9-AZ9)/AZ9 -> #DIV/0! | BO9: =(BH9-AW9)/AW9 -> #DIV/0! | BP9: =BS9 + ABS(BQ9) + ABS(BR9) -> 0 | BW9: FALSE | BX9: FALSE | BY9: =(BT9-BI9)/BI9 -> #DIV/0! | BZ9: =(BS9-BH9)/BH9 -> #DIV/0! | CA9: =CD9 + ABS(CB9) + ABS(CC9) -> 0 | CH9: FALSE | CI9: FALSE | CJ9: =(CE9-BV9)/BV9 -> #DIV/0! | CK9: =(CD9-BS9)/BS9 -> #DIV/0! | CL9: =CO9 + ABS(CM9) + ABS(CN9) -> 0 | CS9: FALSE | CT9: FALSE | CU9: =(CP9-CE9)/CE9 -> #DIV/0! | CV9: =(CO9-CD9)/CD9 -> #DIV/0! | CW9: =CZ9 + ABS(CX9) + ABS(CY9) -> 0 | DD9: FALSE | DE9: FALSE | DF9: =(DA9-CR9)/CR9 -> #DIV/0! | DG9: =(CZ9-CO9)/CO9 -> #DIV/0! | DH9: =DK9 + ABS(DI9) + ABS(DJ9) -> 0 | DO9: FALSE | DP9: FALSE | DQ9: =(DL9-DA9)/DA9 -> #DIV/0! | DR9: =(DK9-CZ9)/CZ9 -> #DIV/0! | DS9: =DV9 + ABS(DT9) + ABS(DU9) -> 0 | DZ9: FALSE | EA9: FALSE | EB9: =(DW9-DN9)/DN9 -> #DIV/0! | EC9: =(DV9-DK9)/DK9 -> #DIV/0! | ED9: =EG9 + ABS(EE9) + ABS(EF9) -> 0 | EK9: FALSE | EL9: FALSE | EM9: =(EH9-DW9)/DW9 -> #DIV/0! | EN9: =(EG9-DV9)/DV9 -> #DIV/0! | EO9: =ER9 + ABS(EP9) + ABS(EQ9) -> 0 | EV9: FALSE | EW9: FALSE | EX9: =(ES9-EJ9)/EJ9 -> #DIV/0! | EY9: =(ER9-EG9)/EG9 -> #DIV/0!
C10: ALMOXARIFADO CENTRAL - DMP ( Parque Norte) | D10: 1450022 | E10: 5 | F10: Y22G1259272 | G10: 00133540464 | H10: COMPANHIA DE SANEAMENTO DE MINAS GERAIS COPASA MG | I10: 17.281.106/0001-03 | N10: 107 | P10: 38.54 | R10: 764.37 | S10: 42 | T10: 1450.01.0005511/2026-51 | X10: =AA10 + ABS(Y10) + ABS(Z10) -> 624.08 | Y10: -29.96 | Z10: 0 | AA10: 594.12 | AB10: 34 | AC10: 10/03/2026 | AD10: 1450.01.0029372/2026-78 | AE10: TRUE | AF10: TRUE | AG10: =(AB10-S10)/S10 -> -0.19047619 | AH10: =(AA10-R10)/R10 -> -0.22273245 | AI10: =AL10 + ABS(AJ10) + ABS(AK10) -> 704.83 | AJ10: -33.83 | AK10: 0 | AL10: 671 | AM10: 36 | AN10: 46122 | AO10: 1450.01.0046622/2026-25 | AP10: TRUE | AQ10: TRUE | AR10: =(AM10-AB10)/AB10 -> 0.058823529 | AS10: =(AL10-AA10)/AA10 -> 0.12940147 | AT10: =AW10 + ABS(AU10) + ABS(AV10) -> 0 | BA10: FALSE | BB10: FALSE | BC10: =(AX10-AM10)/AM10 -> -1 | BD10: =(AW10-AL10)/AL10 -> -1 | BE10: =BH10 + ABS(BF10) + ABS(BG10) -> 0 | BL10: FALSE | BM10: FALSE | BN10: =(BI10-AZ10)/AZ10 -> #DIV/0! | BO10: =(BH10-AW10)/AW10 -> #DIV/0! | BP10: =BS10 + ABS(BQ10) + ABS(BR10) -> 0 | BW10: FALSE | BX10: FALSE | BY10: =(BT10-BI10)/BI10 -> #DIV/0! | BZ10: =(BS10-BH10)/BH10 -> #DIV/0! | CA10: =CD10 + ABS(CB10) + ABS(CC10) -> 0 | CH10: FALSE | CI10: FALSE | CJ10: =(CE10-BV10)/BV10 -> #DIV/0! | CK10: =(CD10-BS10)/BS10 -> #DIV/0! | CL10: =CO10 + ABS(CM10) + ABS(CN10) -> 0 | CS10: FALSE | CT10: FALSE | CU10: =(CP10-CE10)/CE10 -> #DIV/0! | CV10: =(CO10-CD10)/CD10 -> #DIV/0! | CW10: =CZ10 + ABS(CX10) + ABS(CY10) -> 0 | DD10: FALSE | DE10: FALSE | DF10: =(DA10-CR10)/CR10 -> #DIV/0! | DG10: =(CZ10-CO10)/CO10 -> #DIV/0! | DH10: =DK10 + ABS(DI10) + ABS(DJ10) -> 0 | DO10: FALSE | DP10: FALSE | DQ10: =(DL10-DA10)/DA10 -> #DIV/0! | DR10: =(DK10-CZ10)/CZ10 -> #DIV/0! | DS10: =DV10 + ABS(DT10) + ABS(DU10) -> 0 | DZ10: FALSE | EA10: FALSE | EB10: =(DW10-DN10)/DN10 -> #DIV/0! | EC10: =(DV10-DK10)/DK10 -> #DIV/0! | ED10: =EG10 + ABS(EE10) + ABS(EF10) -> 0 | EK10: FALSE | EL10: FALSE | EM10: =(EH10-DW10)/DW10 -> #DIV/0! | EN10: =(EG10-DV10)/DV10 -> #DIV/0! | EO10: =ER10 + ABS(EP10) + ABS(EQ10) -> 0 | EV10: FALSE | EW10: FALSE | EX10: =(ES10-EJ10)/EJ10 -> #DIV/0! | EY10: =(ER10-EG10)/EG10 -> #DIV/0!
C11: CASA DO ALBERGADO PRESIDENTE JOÃO PESSOA | D11: 1450022 | E11: 50 | F11: E25H0000317 | G11: 00011368799 | H11: COMPANHIA DE SANEAMENTO DE MINAS GERAIS COPASA MG | I11: 17.281.106/0001-03 | N11: 107 | P11: 99.06 | R11: 1964.62 | S11: 91 | T11: 1450.01.0005511/2026-51 | X11: =AA11 + ABS(Y11) + ABS(Z11) -> 1322.23 | Y11: -63.47 | Z11: 0 | AA11: 1258.76 | AB11: 62 | AC11: 10/03/2026 | AD11: 1450.01.0029372/2026-78 | AE11: TRUE | AF11: TRUE | AG11: =(AB11-S11)/S11 -> -0.31868132 | AH11: =(AA11-R11)/R11 -> -0.35928577 | AI11: =AL11 + ABS(AJ11) + ABS(AK11) -> 33810.05 | AJ11: -1622.88 | AK11: 0 | AL11: 32187.17 | AM11: 1104 | AN11: 46122 | AO11: 1450.01.0046622/2026-25 | AP11: TRUE | AQ11: TRUE | AR11: =(AM11-AB11)/AB11 -> 16.806452 | AS11: =(AL11-AA11)/AA11 -> 24.570538 | AT11: =AW11 + ABS(AU11) + ABS(AV11) -> 0 | BA11: FALSE | BB11: FALSE | BC11: =(AX11-AM11)/AM11 -> -1 | BD11: =(AW11-AL11)/AL11 -> -1 | BE11: =BH11 + ABS(BF11) + ABS(BG11) -> 0 | BL11: FALSE | BM11: FALSE | BN11: =(BI11-AZ11)/AZ11 -> #DIV/0! | BO11: =(BH11-AW11)/AW11 -> #DIV/0! | BP11: =BS11 + ABS(BQ11) + ABS(BR11) -> 0 | BW11: FALSE | BX11: FALSE | BY11: =(BT11-BI11)/BI11 -> #DIV/0! | BZ11: =(BS11-BH11)/BH11 -> #DIV/0! | CA11: =CD11 + ABS(CB11) + ABS(CC11) -> 0 | CH11: FALSE | CI11: FALSE | CJ11: =(CE11-BV11)/BV11 -> #DIV/0! | CK11: =(CD11-BS11)/BS11 -> #DIV/0! | CL11: =CO11 + ABS(CM11) + ABS(CN11) -> 0 | CS11: FALSE | CT11: FALSE | CU11: =(CP11-CE11)/CE11 -> #DIV/0! | CV11: =(CO11-CD11)/CD11 -> #DIV/0! | CW11: =CZ11 + ABS(CX11) + ABS(CY11) -> 0 | DD11: FALSE | DE11: FALSE | DF11: =(DA11-CR11)/CR11 -> #DIV/0! | DG11: =(CZ11-CO11)/CO11 -> #DIV/0! | DH11: =DK11 + ABS(DI11) + ABS(DJ11) -> 0 | DO11: FALSE | DP11: FALSE | DQ11: =(DL11-DA11)/DA11 -> #DIV/0! | DR11: =(DK11-CZ11)/CZ11 -> #DIV/0! | DS11: =DV11 + ABS(DT11) + ABS(DU11) -> 0 | DZ11: FALSE | EA11: FALSE | EB11: =(DW11-DN11)/DN11 -> #DIV/0! | EC11: =(DV11-DK11)/DK11 -> #DIV/0! | ED11: =EG11 + ABS(EE11) + ABS(EF11) -> 0 | EK11: FALSE | EL11: FALSE | EM11: =(EH11-DW11)/DW11 -> #DIV/0! | EN11: =(EG11-DV11)/DV11 -> #DIV/0! | EO11: =ER11 + ABS(EP11) + ABS(EQ11) -> 0 | EV11: FALSE | EW11: FALSE | EX11: =(ES11-EJ11)/EJ11 -> #DIV/0! | EY11: =(ER11-EG11)/EG11 -> #DIV/0!
C12: CASA DO ALBERGADO PRESIDENTE JOÃO PESSOA | D12: 1450022 | E12: 50 | F12: D17B0704493 | G12: 00027029697 | H12: COMPANHIA DE SANEAMENTO DE MINAS GERAIS COPASA MG | I12: 17.281.106/0001-03 | N12: 107 | P12: 245.29 | R12: 4865 | S12: 208 | T12: 1450.01.0005511/2026-51 | X12: =AA12 + ABS(Y12) + ABS(Z12) -> 5430.52 | Y12: -260.66 | Z12: 0 | AA12: 5169.86 | AB12: 218 | AC12: 10/03/2026 | AD12: 1450.01.0029372/2026-78 | AE12: TRUE | AF12: TRUE | AG12: =(AB12-S12)/S12 -> 0.048076923 | AH12: =(AA12-R12)/R12 -> 0.062663926 | AI12: =AL12 + ABS(AJ12) + ABS(AK12) -> 5591.41 | AJ12: -268.39 | AK12: 0 | AL12: 5323.02 | AM12: 215 | AN12: 46122 | AO12: 1450.01.0046622/2026-25 | AP12: TRUE | AQ12: TRUE | AR12: =(AM12-AB12)/AB12 -> -0.013761468 | AS12: =(AL12-AA12)/AA12 -> 0.02962556 | AT12: =AW12 + ABS(AU12) + ABS(AV12) -> 0 | BA12: FALSE | BB12: FALSE | BC12: =(AX12-AM12)/AM12 -> -1 | BD12: =(AW12-AL12)/AL12 -> -1 | BE12: =BH12 + ABS(BF12) + ABS(BG12) -> 0 | BL12: FALSE | BM12: FALSE | BN12: =(BI12-AZ12)/AZ12 -> #DIV/0! | BO12: =(BH12-AW12)/AW12 -> #DIV/0! | BP12: =BS12 + ABS(BQ12) + ABS(BR12) -> 0 | BW12: FALSE | BX12: FALSE | BY12: =(BT12-BI12)/BI12 -> #DIV/0! | BZ12: =(BS12-BH12)/BH12 -> #DIV/0! | CA12: =CD12 + ABS(CB12) + ABS(CC12) -> 0 | CH12: FALSE | CI12: FALSE | CJ12: =(CE12-BV12)/BV12 -> #DIV/0! | CK12: =(CD12-BS12)/BS12 -> #DIV/0! | CL12: =CO12 + ABS(CM12) + ABS(CN12) -> 0 | CS12: FALSE | CT12: FALSE | CU12: =(CP12-CE12)/CE12 -> #DIV/0! | CV12: =(CO12-CD12)/CD12 -> #DIV/0! | CW12: =CZ12 + ABS(CX12) + ABS(CY12) -> 0 | DD12: FALSE | DE12: FALSE | DF12: =(DA12-CR12)/CR12 -> #DIV/0! | DG12: =(CZ12-CO12)/CO12 -> #DIV/0! | DH12: =DK12 + ABS(DI12) + ABS(DJ12) -> 0 | DO12: FALSE | DP12: FALSE | DQ12: =(DL12-DA12)/DA12 -> #DIV/0! | DR12: =(DK12-CZ12)/CZ12 -> #DIV/0! | DS12: =DV12 + ABS(DT12) + ABS(DU12) -> 0 | DZ12: FALSE | EA12: FALSE | EB12: =(DW12-DN12)/DN12 -> #DIV/0! | EC12: =(DV12-DK12)/DK12 -> #DIV/0! | ED12: =EG12 + ABS(EE12) + ABS(EF12) -> 0 | EK12: FALSE | EL12: FALSE | EM12: =(EH12-DW12)/DW12 -> #DIV/0! | EN12: =(EG12-DV12)/DV12 -> #DIV/0! | EO12: =ER12 + ABS(EP12) + ABS(EQ12) -> 0 | EV12: FALSE | EW12: FALSE | EX12: =(ES12-EJ12)/EJ12 -> #DIV/0! | EY12: =(ER12-EG12)/EG12 -> #DIV/0!
C13: CENTRAL DE FLAGRANTES | D13: 1450022 | E13: 282 | F13: A19N0415854 | G13: 00000693537 | H13: COMPANHIA DE SANEAMENTO DE MINAS GERAIS COPASA MG | I13: 17.281.106/0001-03 | N13: 107 | P13: 45.95 | R13: 911.34 | S13: 48 | T13: 1450.01.0005511/2026-51 | X13: =AA13 + ABS(Y13) + ABS(Z13) -> 883.44 | Y13: -42.41 | Z13: 0 | AA13: 841.03 | AB13: 45 | AC13: 10/03/2026 | AD13: 1450.01.0029372/2026-78 | AE13: TRUE | AF13: TRUE | AG13: =(AB13-S13)/S13 -> -0.0625 | AH13: =(AA13-R13)/R13 -> -0.077150131 | AI13: =AL13 + ABS(AJ13) + ABS(AK13) -> 985.81 | AJ13: -47.32 | AK13: 0 | AL13: 938.49 | AM13: 47 | AN13: 46122 | AO13: 1450.01.0046622/2026-25 | AP13: TRUE | AQ13: TRUE | AR13: =(AM13-AB13)/AB13 -> 0.044444444 | AS13: =(AL13-AA13)/AA13 -> 0.11588172 | AT13: =AW13 + ABS(AU13) + ABS(AV13) -> 0 | BA13: FALSE | BB13: FALSE | BC13: =(AX13-AM13)/AM13 -> -1 | BD13: =(AW13-AL13)/AL13 -> -1 | BE13: =BH13 + ABS(BF13) + ABS(BG13) -> 0 | BL13: FALSE | BM13: FALSE | BN13: =(BI13-AZ13)/AZ13 -> #DIV/0! | BO13: =(BH13-AW13)/AW13 -> #DIV/0! | BP13: =BS13 + ABS(BQ13) + ABS(BR13) -> 0 | BW13: FALSE | BX13: FALSE | BY13: =(BT13-BI13)/BI13 -> #DIV/0! | BZ13: =(BS13-BH13)/BH13 -> #DIV/0! | CA13: =CD13 + ABS(CB13) + ABS(CC13) -> 0 | CH13: FALSE | CI13: FALSE | CJ13: =(CE13-BV13)/BV13 -> #DIV/0! | CK13: =(CD13-BS13)/BS13 -> #DIV/0! | CL13: =CO13 + ABS(CM13) + ABS(CN13) -> 0 | CS13: FALSE | CT13: FALSE | CU13: =(CP13-CE13)/CE13 -> #DIV/0! | CV13: =(CO13-CD13)/CD13 -> #DIV/0! | CW13: =CZ13 + ABS(CX13) + ABS(CY13) -> 0 | DD13: FALSE | DE13: FALSE | DF13: =(DA13-CR13)/CR13 -> #DIV/0! | DG13: =(CZ13-CO13)/CO13 -> #DIV/0! | DH13: =DK13 + ABS(DI13) + ABS(DJ13) -> 0 | DO13: FALSE | DP13: FALSE | DQ13: =(DL13-DA13)/DA13 -> #DIV/0! | DR13: =(DK13-CZ13)/CZ13 -> #DIV/0! | DS13: =DV13 + ABS(DT13) + ABS(DU13) -> 0 | DZ13: FALSE | EA13: FALSE | EB13: =(DW13-DN13)/DN13 -> #DIV/0! | EC13: =(DV13-DK13)/DK13 -> #DIV/0! | ED13: =EG13 + ABS(EE13) + ABS(EF13) -> 0 | EK13: FALSE | EL13: FALSE | EM13: =(EH13-DW13)/DW13 -> #DIV/0! | EN13: =(EG13-DV13)/DV13 -> #DIV/0! | EO13: =ER13 + ABS(EP13) + ABS(EQ13) -> 0 | EV13: FALSE | EW13: FALSE | EX13: =(ES13-EJ13)/EJ13 -> #DIV/0! | EY13: =(ER13-EG13)/EG13 -> #DIV/0!
C14: CERESP BETIM | D14: 1450022 | E14: 85 | F14: E17B0791102 G23C8001998 | G14: 00109188632 | H14: COMPANHIA DE SANEAMENTO DE MINAS GERAIS COPASA MG | I14: 17.281.106/0001-03 | N14: 107 | P14: 9263.7 | R14: 183730.14 | S14: 6418 | T14: 1450.01.0005511/2026-51 | X14: =AA14 + ABS(Y14) + ABS(Z14) -> 237196.39 | Y14: -11385.43 | Z14: 0 | AA14: 225810.96 | AB14: 7879 | AC14: 10/03/2026 | AD14: 1450.01.0029372/2026-78 | AE14: TRUE | AF14: TRUE | AG14: =(AB14-S14)/S14 -> 0.22764101 | AH14: =(AA14-R14)/R14 -> 0.22903602 | AI14: =AL14 + ABS(AJ14) + ABS(AK14) -> 232539.57 | AJ14: -11161.9 | AK14: 0 | AL14: 221377.67 | AM14: 7522 | AN14: 46122 | AO14: 1450.01.0046622/2026-25 | AP14: TRUE | AQ14: TRUE | AR14: =(AM14-AB14)/AB14 -> -0.045310319 | AS14: =(AL14-AA14)/AA14 -> -0.019632749 | AT14: =AW14 + ABS(AU14) + ABS(AV14) -> 0 | BA14: FALSE | BB14: FALSE | BC14: =(AX14-AM14)/AM14 -> -1 | BD14: =(AW14-AL14)/AL14 -> -1 | BE14: =BH14 + ABS(BF14) + ABS(BG14) -> 0 | BL14: FALSE | BM14: FALSE | BN14: =(BI14-AZ14)/AZ14 -> #DIV/0! | BO14: =(BH14-AW14)/AW14 -> #DIV/0! | BP14: =BS14 + ABS(BQ14) + ABS(BR14) -> 0 | BW14: FALSE | BX14: FALSE | BY14: =(BT14-BI14)/BI14 -> #DIV/0! | BZ14: =(BS14-BH14)/BH14 -> #DIV/0! | CA14: =CD14 + ABS(CB14) + ABS(CC14) -> 0 | CH14: FALSE | CI14: FALSE | CJ14: =(CE14-BV14)/BV14 -> #DIV/0! | CK14: =(CD14-BS14)/BS14 -> #DIV/0! | CL14: =CO14 + ABS(CM14) + ABS(CN14) -> 0 | CS14: FALSE | CT14: FALSE | CU14: =(CP14-CE14)/CE14 -> #DIV/0! | CV14: =(CO14-CD14)/CD14 -> #DIV/0! | CW14: =CZ14 + ABS(CX14) + ABS(CY14) -> 0 | DD14: FALSE | DE14: FALSE | DF14: =(DA14-CR14)/CR14 -> #DIV/0! | DG14: =(CZ14-CO14)/CO14 -> #DIV/0! | DH14: =DK14 + ABS(DI14) + ABS(DJ14) -> 0 | DO14: FALSE | DP14: FALSE | DQ14: =(DL14-DA14)/DA14 -> #DIV/0! | DR14: =(DK14-CZ14)/CZ14 -> #DIV/0! | DS14: =DV14 + ABS(DT14) + ABS(DU14) -> 0 | DZ14: FALSE | EA14: FALSE | EB14: =(DW14-DN14)/DN14 -> #DIV/0! | EC14: =(DV14-DK14)/DK14 -> #DIV/0! | ED14: =EG14 + ABS(EE14) + ABS(EF14) -> 0 | EK14: FALSE | EL14: FALSE | EM14: =(EH14-DW14)/DW14 -> #DIV/0! | EN14: =(EG14-DV14)/DV14 -> #DIV/0! | EO14: =ER14 + ABS(EP14) + ABS(EQ14) -> 0 | EV14: FALSE | EW14: FALSE | EX14: =(ES14-EJ14)/EJ14 -> #DIV/0! | EY14: =(ER14-EG14)/EG14 -> #DIV/0!
C15: CERESP CONTAGEM | D15: 1450022 | E15: 136 | F15: D17B0705014 | G15: 00002251426 | H15: COMPANHIA DE SANEAMENTO DE MINAS GERAIS COPASA MG | I15: 17.281.106/0001-03 | N15: 107 | P15: 284.5 | R15: 5642.68 | S15: 235 | T15: 1450.01.0005511/2026-51 | X15: =AA15 + ABS(Y15) + ABS(Z15) -> 16758.46 | Y15: -804.41 | Z15: 0 | AA15: 15954.05 | AB15: 593 | AC15: 10/03/2026 | AD15: 1450.01.0029372/2026-78 | AE15: TRUE | AF15: TRUE | AG15: =(AB15-S15)/S15 -> 1.5234043 | AH15: =(AA15-R15)/R15 -> 1.8273888 | AI15: =AL15 + ABS(AJ15) + ABS(AK15) -> 16160.55 | AJ15: -775.71 | AK15: 0 | AL15: 15384.84 | AM15: 553 | AN15: 46122 | AO15: 1450.01.0046622/2026-25 | AP15: TRUE | AQ15: TRUE | AR15: =(AM15-AB15)/AB15 -> -0.067453626 | AS15: =(AL15-AA15)/AA15 -> -0.035678088 | AT15: =AW15 + ABS(AU15) + ABS(AV15) -> 0 | BA15: FALSE | BB15: FALSE | BC15: =(AX15-AM15)/AM15 -> -1 | BD15: =(AW15-AL15)/AL15 -> -1 | BE15: =BH15 + ABS(BF15) + ABS(BG15) -> 0 | BL15: FALSE | BM15: FALSE | BN15: =(BI15-AZ15)/AZ15 -> #DIV/0! | BO15: =(BH15-AW15)/AW15 -> #DIV/0! | BP15: =BS15 + ABS(BQ15) + ABS(BR15) -> 0 | BW15: FALSE | BX15: FALSE | BY15: =(BT15-BI15)/BI15 -> #DIV/0! | BZ15: =(BS15-BH15)/BH15 -> #DIV/0! | CA15: =CD15 + ABS(CB15) + ABS(CC15) -> 0 | CH15: FALSE | CI15: FALSE | CJ15: =(CE15-BV15)/BV15 -> #DIV/0! | CK15: =(CD15-BS15)/BS15 -> #DIV/0! | CL15: =CO15 + ABS(CM15) + ABS(CN15) -> 0 | CS15: FALSE | CT15: FALSE | CU15: =(CP15-CE15)/CE15 -> #DIV/0! | CV15: =(CO15-CD15)/CD15 -> #DIV/0! | CW15: =CZ15 + ABS(CX15) + ABS(CY15) -> 0 | DD15: FALSE | DE15: FALSE | DF15: =(DA15-CR15)/CR15 -> #DIV/0! | DG15: =(CZ15-CO15)/CO15 -> #DIV/0! | DH15: =DK15 + ABS(DI15) + ABS(DJ15) -> 0 | DO15: FALSE | DP15: FALSE | DQ15: =(DL15-DA15)/DA15 -> #DIV/0! | DR15: =(DK15-CZ15)/CZ15 -> #DIV/0! | DS15: =DV15 + ABS(DT15) + ABS(DU15) -> 0 | DZ15: FALSE | EA15: FALSE | EB15: =(DW15-DN15)/DN15 -> #DIV/0! | EC15: =(DV15-DK15)/DK15 -> #DIV/0! | ED15: =EG15 + ABS(EE15) + ABS(EF15) -> 0 | EK15: FALSE | EL15: FALSE | EM15: =(EH15-DW15)/DW15 -> #DIV/0! | EN15: =(EG15-DV15)/DV15 -> #DIV/0! | EO15: =ER15 + ABS(EP15) + ABS(EQ15) -> 0 | EV15: FALSE | EW15: FALSE | EX15: =(ES15-EJ15)/EJ15 -> #DIV/0! | EY15: =(ER15-EG15)/EG15 -> #DIV/0!
C16: CERESP GAMELEIRA | D16: 1450022 | E16: 86 | F16: G23C8002161 G22C8100030 | G16: 00002027461 | H16: COMPANHIA DE SANEAMENTO DE MINAS GERAIS COPASA MG | I16: 17.281.106/0001-03 | N16: 107 | P16: 18235.64 | R16: 361673.59 | S16: 12596 | T16: 1450.01.0005511/2026-51 | X16: =AA16 + ABS(Y16) + ABS(Z16) -> 450100.83 | Y16: -21604.84 | Z16: 0 | AA16: 428495.99 | AB16: 14916 | AC16: 10/03/2026 | AD16: 1450.01.0029372/2026-78 | AE16: TRUE | AF16: TRUE | AG16: =(AB16-S16)/S16 -> 0.18418546 | AH16: =(AA16-R16)/R16 -> 0.18475886 | AI16: =AL16 + ABS(AJ16) + ABS(AK16) -> 262626.58 | AJ16: -12606.08 | AK16: 0 | AL16: 250020.5 | AM16: 8421 | AN16: 46122 | AO16: 1450.01.0046622/2026-25 | AP16: TRUE | AQ16: TRUE | AR16: =(AM16-AB16)/AB16 -> -0.43543846 | AS16: =(AL16-AA16)/AA16 -> -0.41651613 | AT16: =AW16 + ABS(AU16) + ABS(AV16) -> 0 | BA16: FALSE | BB16: FALSE | BC16: =(AX16-AM16)/AM16 -> -1 | BD16: =(AW16-AL16)/AL16 -> -1 | BE16: =BH16 + ABS(BF16) + ABS(BG16) -> 0 | BL16: FALSE | BM16: FALSE | BN16: =(BI16-AZ16)/AZ16 -> #DIV/0! | BO16: =(BH16-AW16)/AW16 -> #DIV/0! | BP16: =BS16 + ABS(BQ16) + ABS(BR16) -> 0 | BW16: FALSE | BX16: FALSE | BY16: =(BT16-BI16)/BI16 -> #DIV/0! | BZ16: =(BS16-BH16)/BH16 -> #DIV/0! | CA16: =CD16 + ABS(CB16) + ABS(CC16) -> 0 | CH16: FALSE | CI16: FALSE | CJ16: =(CE16-BV16)/BV16 -> #DIV/0! | CK16: =(CD16-BS16)/BS16 -> #DIV/0! | CL16: =CO16 + ABS(CM16) + ABS(CN16) -> 0 | CS16: FALSE | CT16: FALSE | CU16: =(CP16-CE16)/CE16 -> #DIV/0! | CV16: =(CO16-CD16)/CD16 -> #DIV/0! | CW16: =CZ16 + ABS(CX16) + ABS(CY16) -> 0 | DD16: FALSE | DE16: FALSE | DF16: =(DA16-CR16)/CR16 -> #DIV/0! | DG16: =(CZ16-CO16)/CO16 -> #DIV/0! | DH16: =DK16 + ABS(DI16) + ABS(DJ16) -> 0 | DO16: FALSE | DP16: FALSE | DQ16: =(DL16-DA16)/DA16 -> #DIV/0! | DR16: =(DK16-CZ16)/CZ16 -> #DIV/0! | DS16: =DV16 + ABS(DT16) + ABS(DU16) -> 0 | DZ16: FALSE | EA16: FALSE | EB16: =(DW16-DN16)/DN16 -> #DIV/0! | EC16: =(DV16-DK16)/DK16 -> #DIV/0! | ED16: =EG16 + ABS(EE16) + ABS(EF16) -> 0 | EK16: FALSE | EL16: FALSE | EM16: =(EH16-DW16)/DW16 -> #DIV/0! | EN16: =(EG16-DV16)/DV16 -> #DIV/0! | EO16: =ER16 + ABS(EP16) + ABS(EQ16) -> 0 | EV16: FALSE | EW16: FALSE | EX16: =(ES16-EJ16)/EJ16 -> #DIV/0! | EY16: =(ER16-EG16)/EG16 -> #DIV/0!
C17: CERESP IPATINGA (Santana do Paraiso) | D17: 1450022 | E17: 106 | F17: E18B0801588 | G17: 00105574660 | H17: COMPANHIA DE SANEAMENTO DE MINAS GERAIS COPASA MG | I17: 17.281.106/0001-03 | N17: 107 | P17: 7436.79 | R17: 147496.26 | S17: 5160 | T17: 1450.01.0005511/2026-51 | X17: =AA17 + ABS(Y17) + ABS(Z17) -> 177321.75 | Y17: -8511.44 | Z17: 0 | AA17: 168810.31 | AB17: 5900 | AC17: 10/03/2026 | AD17: 1450.01.0029372/2026-78 | AE17: TRUE | AF17: TRUE | AG17: =(AB17-S17)/S17 -> 0.14341085 | AH17: =(AA17-R17)/R17 -> 0.1445057 | AI17: =AL17 + ABS(AJ17) + ABS(AK17) -> 150467.34 | AJ17: -7222.43 | AK17: 0 | AL17: 143244.91 | AM17: 4897 | AN17: 46122 | AO17: 1450.01.0046622/2026-25 | AP17: TRUE | AQ17: TRUE | AR17: =(AM17-AB17)/AB17 -> -0.17 | AS17: =(AL17-AA17)/AA17 -> -0.15144454 | AT17: =AW17 + ABS(AU17) + ABS(AV17) -> 0 | BA17: FALSE | BB17: FALSE | BC17: =(AX17-AM17)/AM17 -> -1 | BD17: =(AW17-AL17)/AL17 -> -1 | BE17: =BH17 + ABS(BF17) + ABS(BG17) -> 0 | BL17: FALSE | BM17: FALSE | BN17: =(BI17-AZ17)/AZ17 -> #DIV/0! | BO17: =(BH17-AW17)/AW17 -> #DIV/0! | BP17: =BS17 + ABS(BQ17) + ABS(BR17) -> 0 | BW17: FALSE | BX17: FALSE | BY17: =(BT17-BI17)/BI17 -> #DIV/0! | BZ17: =(BS17-BH17)/BH17 -> #DIV/0! | CA17: =CD17 + ABS(CB17) + ABS(CC17) -> 0 | CH17: FALSE | CI17: FALSE | CJ17: =(CE17-BV17)/BV17 -> #DIV/0! | CK17: =(CD17-BS17)/BS17 -> #DIV/0! | CL17: =CO17 + ABS(CM17) + ABS(CN17) -> 0 | CS17: FALSE | CT17: FALSE | CU17: =(CP17-CE17)/CE17 -> #DIV/0! | CV17: =(CO17-CD17)/CD17 -> #DIV/0! | CW17: =CZ17 + ABS(CX17) + ABS(CY17) -> 0 | DD17: FALSE | DE17: FALSE | DF17: =(DA17-CR17)/CR17 -> #DIV/0! | DG17: =(CZ17-CO17)/CO17 -> #DIV/0! | DH17: =DK17 + ABS(DI17) + ABS(DJ17) -> 0 | DO17: FALSE | DP17: FALSE | DQ17: =(DL17-DA17)/DA17 -> #DIV/0! | DR17: =(DK17-CZ17)/CZ17 -> #DIV/0! | DS17: =DV17 + ABS(DT17) + ABS(DU17) -> 0 | DZ17: FALSE | EA17: FALSE | EB17: =(DW17-DN17)/DN17 -> #DIV/0! | EC17: =(DV17-DK17)/DK17 -> #DIV/0! | ED17: =EG17 + ABS(EE17) + ABS(EF17) -> 0 | EK17: FALSE | EL17: FALSE | EM17: =(EH17-DW17)/DW17 -> #DIV/0! | EN17: =(EG17-DV17)/DV17 -> #DIV/0! | EO17: =ER17 + ABS(EP17) + ABS(EQ17) -> 0 | EV17: FALSE | EW17: FALSE | EX17: =(ES17-EJ17)/EJ17 -> #DIV/0! | EY17: =(ER17-EG17)/EG17 -> #DIV/0!
C18: COMPLEXO PENITENCIÁRIO ESTEVÃO PINTO | D18: 1450022 | E18: 27 | F18: D17B7045870 | G18: 00119083850 | H18: COMPANHIA DE SANEAMENTO DE MINAS GERAIS COPASA MG | I18: 17.281.106/0001-03 | N18: 107 | P18: 2927.58 | R18: 58063.7 | S18: 2055 | T18: 1450.01.0005511/2026-51 | X18: =AA18 + ABS(Y18) + ABS(Z18) -> 33748.06 | Y18: -1619.91 | Z18: 0 | AA18: 32128.15 | AB18: 1151 | AC18: 10/03/2026 | AD18: 1450.01.0029372/2026-78 | AE18: TRUE | AF18: TRUE | AG18: =(AB18-S18)/S18 -> -0.43990268 | AH18: =(AA18-R18)/R18 -> -0.44667408 | AI18: =AL18 + ABS(AJ18) + ABS(AK18) -> 32032.5 | AJ18: -1537.56 | AK18: 0 | AL18: 30494.94 | AM18: 1048 | AN18: 46122 | AO18: 1450.01.0046622/2026-25 | AP18: TRUE | AQ18: TRUE | AR18: =(AM18-AB18)/AB18 -> -0.089487402 | AS18: =(AL18-AA18)/AA18 -> -0.050834237 | AT18: =AW18 + ABS(AU18) + ABS(AV18) -> 0 | BA18: FALSE | BB18: FALSE | BC18: =(AX18-AM18)/AM18 -> -1 | BD18: =(AW18-AL18)/AL18 -> -1 | BE18: =BH18 + ABS(BF18) + ABS(BG18) -> 0 | BL18: FALSE | BM18: FALSE | BN18: =(BI18-AZ18)/AZ18 -> #DIV/0! | BO18: =(BH18-AW18)/AW18 -> #DIV/0! | BP18: =BS18 + ABS(BQ18) + ABS(BR18) -> 0 | BW18: FALSE | BX18: FALSE | BY18: =(BT18-BI18)/BI18 -> #DIV/0! | BZ18: =(BS18-BH18)/BH18 -> #DIV/0! | CA18: =CD18 + ABS(CB18) + ABS(CC18) -> 0 | CH18: FALSE | CI18: FALSE | CJ18: =(CE18-BV18)/BV18 -> #DIV/0! | CK18: =(CD18-BS18)/BS18 -> #DIV/0! | CL18: =CO18 + ABS(CM18) + ABS(CN18) -> 0 | CS18: FALSE | CT18: FALSE | CU18: =(CP18-CE18)/CE18 -> #DIV/0! | CV18: =(CO18-CD18)/CD18 -> #DIV/0! | CW18: =CZ18 + ABS(CX18) + ABS(CY18) -> 0 | DD18: FALSE | DE18: FALSE | DF18: =(DA18-CR18)/CR18 -> #DIV/0! | DG18: =(CZ18-CO18)/CO18 -> #DIV/0! | DH18: =DK18 + ABS(DI18) + ABS(DJ18) -> 0 | DO18: FALSE | DP18: FALSE | DQ18: =(DL18-DA18)/DA18 -> #DIV/0! | DR18: =(DK18-CZ18)/CZ18 -> #DIV/0! | DS18: =DV18 + ABS(DT18) + ABS(DU18) -> 0 | DZ18: FALSE | EA18: FALSE | EB18: =(DW18-DN18)/DN18 -> #DIV/0! | EC18: =(DV18-DK18)/DK18 -> #DIV/0! | ED18: =EG18 + ABS(EE18) + ABS(EF18) -> 0 | EK18: FALSE | EL18: FALSE | EM18: =(EH18-DW18)/DW18 -> #DIV/0! | EN18: =(EG18-DV18)/DV18 -> #DIV/0! | EO18: =ER18 + ABS(EP18) + ABS(EQ18) -> 0 | EV18: FALSE | EW18: FALSE | EX18: =(ES18-EJ18)/EJ18 -> #DIV/0! | EY18: =(ER18-EG18)/EG18 -> #DIV/0!
C19: COMPLEXO PENITENCIÁRIO ESTEVÃO PINTO | D19: 1450022 | E19: 27 | F19: F18B0901260 | G19: 00011368802 | H19: COMPANHIA DE SANEAMENTO DE MINAS GERAIS COPASA MG | I19: 17.281.106/0001-03 | N19: 107 | P19: 4854.7 | R19: 96284.96 | S19: 3382 | T19: 1450.01.0005511/2026-51 | X19: =AA19 + ABS(Y19) + ABS(Z19) -> 101097.07 | Y19: -4852.66 | Z19: 0 | AA19: 96244.41 | AB19: 3370 | AC19: 10/03/2026 | AD19: 1450.01.0029372/2026-78 | AE19: TRUE | AF19: TRUE | AG19: =(AB19-S19)/S19 -> -0.0035481963 | AH19: =(AA19-R19)/R19 -> -0.00042114573 | AI19: =AL19 + ABS(AJ19) + ABS(AK19) -> 101928.38 | AJ19: -4892.56 | AK19: 0 | AL19: 97035.82 | AM19: 3250 | AN19: 46122 | AO19: 1450.01.0046622/2026-25 | AP19: TRUE | AQ19: TRUE | AR19: =(AM19-AB19)/AB19 -> -0.035608309 | AS19: =(AL19-AA19)/AA19 -> 0.0082229191 | AT19: =AW19 + ABS(AU19) + ABS(AV19) -> 0 | BA19: FALSE | BB19: FALSE | BC19: =(AX19-AM19)/AM19 -> -1 | BD19: =(AW19-AL19)/AL19 -> -1 | BE19: =BH19 + ABS(BF19) + ABS(BG19) -> 0 | BL19: FALSE | BM19: FALSE | BN19: =(BI19-AZ19)/AZ19 -> #DIV/0! | BO19: =(BH19-AW19)/AW19 -> #DIV/0! | BP19: =BS19 + ABS(BQ19) + ABS(BR19) -> 0 | BW19: FALSE | BX19: FALSE | BY19: =(BT19-BI19)/BI19 -> #DIV/0! | BZ19: =(BS19-BH19)/BH19 -> #DIV/0! | CA19: =CD19 + ABS(CB19) + ABS(CC19) -> 0 | CH19: FALSE | CI19: FALSE | CJ19: =(CE19-BV19)/BV19 -> #DIV/0! | CK19: =(CD19-BS19)/BS19 -> #DIV/0! | CL19: =CO19 + ABS(CM19) + ABS(CN19) -> 0 | CS19: FALSE | CT19: FALSE | CU19: =(CP19-CE19)/CE19 -> #DIV/0! | CV19: =(CO19-CD19)/CD19 -> #DIV/0! | CW19: =CZ19 + ABS(CX19) + ABS(CY19) -> 0 | DD19: FALSE | DE19: FALSE | DF19: =(DA19-CR19)/CR19 -> #DIV/0! | DG19: =(CZ19-CO19)/CO19 -> #DIV/0! | DH19: =DK19 + ABS(DI19) + ABS(DJ19) -> 0 | DO19: FALSE | DP19: FALSE | DQ19: =(DL19-DA19)/DA19 -> #DIV/0! | DR19: =(DK19-CZ19)/CZ19 -> #DIV/0! | DS19: =DV19 + ABS(DT19) + ABS(DU19) -> 0 | DZ19: FALSE | EA19: FALSE | EB19: =(DW19-DN19)/DN19 -> #DIV/0! | EC19: =(DV19-DK19)/DK19 -> #DIV/0! | ED19: =EG19 + ABS(EE19) + ABS(EF19) -> 0 | EK19: FALSE | EL19: FALSE | EM19: =(EH19-DW19)/DW19 -> #DIV/0! | EN19: =(EG19-DV19)/DV19 -> #DIV/0! | EO19: =ER19 + ABS(EP19) + ABS(EQ19) -> 0 | EV19: FALSE | EW19: FALSE | EX19: =(ES19-EJ19)/EJ19 -> #DIV/0! | EY19: =(ER19-EG19)/EG19 -> #DIV/0!
C20: COMPLEXO PENIT. NELSON HUNGRIA | D20: 1450022 | E20: 36 | F20: K22D2510787 | G20: 00017213169 | H20: COMPANHIA DE SANEAMENTO DE MINAS GERAIS COPASA MG | I20: 17.281.106/0001-03 | N20: 107 | P20: 38164.73 | R20: 756933.86 | S20: 26319 | T20: 1450.01.0005511/2026-51 | X20: =AA20 + ABS(Y20) + ABS(Z20) -> 1021755.1 | Y20: -49044.24 | Z20: 0 | AA20: 972710.81 | AB20: 33757 | AC20: 10/03/2026 | AD20: 1450.01.0029372/2026-78 | AE20: TRUE | AF20: TRUE | AG20: =(AB20-S20)/S20 -> 0.28260952 | AH20: =(AA20-R20)/R20 -> 0.28506711 | AI20: =AL20 + ABS(AJ20) + ABS(AK20) -> 766256.7 | AJ20: -36780.32 | AK20: 0 | AL20: 729476.38 | AM20: 24179 | AN20: 46122 | AO20: 1450.01.0046622/2026-25 | AP20: TRUE | AQ20: TRUE | AR20: =(AM20-AB20)/AB20 -> -0.28373374 | AS20: =(AL20-AA20)/AA20 -> -0.25005832 | AT20: =AW20 + ABS(AU20) + ABS(AV20) -> 0 | BA20: FALSE | BB20: FALSE | BC20: =(AX20-AM20)/AM20 -> -1 | BD20: =(AW20-AL20)/AL20 -> -1 | BE20: =BH20 + ABS(BF20) + ABS(BG20) -> 0 | BL20: FALSE | BM20: FALSE | BN20: =(BI20-AZ20)/AZ20 -> #DIV/0! | BO20: =(BH20-AW20)/AW20 -> #DIV/0! | BP20: =BS20 + ABS(BQ20) + ABS(BR20) -> 0 | BW20: FALSE | BX20: FALSE | BY20: =(BT20-BI20)/BI20 -> #DIV/0! | BZ20: =(BS20-BH20)/BH20 -> #DIV/0! | CA20: =CD20 + ABS(CB20) + ABS(CC20) -> 0 | CH20: FALSE | CI20: FALSE | CJ20: =(CE20-BV20)/BV20 -> #DIV/0! | CK20: =(CD20-BS20)/BS20 -> #DIV/0! | CL20: =CO20 + ABS(CM20) + ABS(CN20) -> 0 | CS20: FALSE | CT20: FALSE | CU20: =(CP20-CE20)/CE20 -> #DIV/0! | CV20: =(CO20-CD20)/CD20 -> #DIV/0! | CW20: =CZ20 + ABS(CX20) + ABS(CY20) -> 0 | DD20: FALSE | DE20: FALSE | DF20: =(DA20-CR20)/CR20 -> #DIV/0! | DG20: =(CZ20-CO20)/CO20 -> #DIV/0! | DH20: =DK20 + ABS(DI20) + ABS(DJ20) -> 0 | DO20: FALSE | DP20: FALSE | DQ20: =(DL20-DA20)/DA20 -> #DIV/0! | DR20: =(DK20-CZ20)/CZ20 -> #DIV/0! | DS20: =DV20 + ABS(DT20) + ABS(DU20) -> 0 | DZ20: FALSE | EA20: FALSE | EB20: =(DW20-DN20)/DN20 -> #DIV/0! | EC20: =(DV20-DK20)/DK20 -> #DIV/0! | ED20: =EG20 + ABS(EE20) + ABS(EF20) -> 0 | EK20: FALSE | EL20: FALSE | EM20: =(EH20-DW20)/DW20 -> #DIV/0! | EN20: =(EG20-DV20)/DV20 -> #DIV/0! | EO20: =ER20 + ABS(EP20) + ABS(EQ20) -> 0 | EV20: FALSE | EW20: FALSE | EX20: =(ES20-EJ20)/EJ20 -> #DIV/0! | EY20: =(ER20-EG20)/EG20 -> #DIV/0!
C21: COMPLEXO PENIT. NOSSA SENH. DO CARMO | D21: 1450022 | E21: 38 | F21: C18D0704419 | G21: 00114881669 | H21: COMPANHIA DE SANEAMENTO DE MINAS GERAIS COPASA MG | I21: 17.281.106/0001-03 | N21: 107 | P21: 1836.95 | R21: 36432.82 | S21: 1304 | T21: 1450.01.0005511/2026-51 | X21: =AA21 + ABS(Y21) + ABS(Z21) -> 50002.75 | Y21: -2400.13 | Z21: 0 | AA21: 47602.62 | AB21: 1673 | AC21: 10/03/2026 | AD21: 1450.01.0029372/2026-78 | AE21: TRUE | AF21: TRUE | AG21: =(AB21-S21)/S21 -> 0.28297546 | AH21: =(AA21-R21)/R21 -> 0.3065862 | AI21: =AL21 + ABS(AJ21) + ABS(AK21) -> 33841.79 | AJ21: -1624.41 | AK21: 0 | AL21: 32217.38 | AM21: 1105 | AN21: 46122 | AO21: 1450.01.0046622/2026-25 | AP21: TRUE | AQ21: TRUE | AR21: =(AM21-AB21)/AB21 -> -0.33950986 | AS21: =(AL21-AA21)/AA21 -> -0.32320154 | AT21: =AW21 + ABS(AU21) + ABS(AV21) -> 0 | BA21: FALSE | BB21: FALSE | BC21: =(AX21-AM21)/AM21 -> -1 | BD21: =(AW21-AL21)/AL21 -> -1 | BE21: =BH21 + ABS(BF21) + ABS(BG21) -> 0 | BL21: FALSE | BM21: FALSE | BN21: =(BI21-AZ21)/AZ21 -> #DIV/0! | BO21: =(BH21-AW21)/AW21 -> #DIV/0! | BP21: =BS21 + ABS(BQ21) + ABS(BR21) -> 0 | BW21: FALSE | BX21: FALSE | BY21: =(BT21-BI21)/BI21 -> #DIV/0! | BZ21: =(BS21-BH21)/BH21 -> #DIV/0! | CA21: =CD21 + ABS(CB21) + ABS(CC21) -> 0 | CH21: FALSE | CI21: FALSE | CJ21: =(CE21-BV21)/BV21 -> #DIV/0! | CK21: =(CD21-BS21)/BS21 -> #DIV/0! | CL21: =CO21 + ABS(CM21) + ABS(CN21) -> 0 | CS21: FALSE | CT21: FALSE | CU21: =(CP21-CE21)/CE21 -> #DIV/0! | CV21: =(CO21-CD21)/CD21 -> #DIV/0! | CW21: =CZ21 + ABS(CX21) + ABS(CY21) -> 0 | DD21: FALSE | DE21: FALSE | DF21: =(DA21-CR21)/CR21 -> #DIV/0! | DG21: =(CZ21-CO21)/CO21 -> #DIV/0! | DH21: =DK21 + ABS(DI21) + ABS(DJ21) -> 0 | DO21: FALSE | DP21: FALSE | DQ21: =(DL21-DA21)/DA21 -> #DIV/0! | DR21: =(DK21-CZ21)/CZ21 -> #DIV/0! | DS21: =DV21 + ABS(DT21) + ABS(DU21) -> 0 | DZ21: FALSE | EA21: FALSE | EB21: =(DW21-DN21)/DN21 -> #DIV/0! | EC21: =(DV21-DK21)/DK21 -> #DIV/0! | ED21: =EG21 + ABS(EE21) + ABS(EF21) -> 0 | EK21: FALSE | EL21: FALSE | EM21: =(EH21-DW21)/DW21 -> #DIV/0! | EN21: =(EG21-DV21)/DV21 -> #DIV/0! | EO21: =ER21 + ABS(EP21) + ABS(EQ21) -> 0 | EV21: FALSE | EW21: FALSE | EX21: =(ES21-EJ21)/EJ21 -> #DIV/0! | EY21: =(ER21-EG21)/EG21 -> #DIV/0!
... C30: PENITENCIÁRIA JOSÉ MARIA ALKIMIM | D30: 1450022 | E30: 35 | F30: Y24G1242371 | G30: 00106360655 | H30: COMPANHIA DE SANEAMENTO DE MINAS GERAIS COPASA MG | I30: 17.281.106/0001-03 | N30: 107 | P30: 7.61 | R30: 150.83 | S30: 10 | T30: 1450.01.0005511/2026-51 | X30: =AA30 + ABS(Y30) + ABS(Z30) -> 158.44 | Y30: -7.61 | Z30: 0 | AA30: 150.83 | AB30: 10 | AC30: 10/03/2026 | AD30: 1450.01.0029372/2026-78 | AE30: TRUE | AF30: TRUE | AG30: =(AB30-S30)/S30 -> 0 | AH30: =(AA30-R30)/R30 -> 0 | AI30: =AL30 + ABS(AJ30) + ABS(AK30) -> 160.33 | AJ30: -7.7 | AK30: 0 | AL30: 152.63 | AM30: 9 | AN30: 46122 | AO30: 1450.01.0046622/2026-25 | AP30: TRUE | AQ30: TRUE | AR30: =(AM30-AB30)/AB30 -> -0.1 | AS30: =(AL30-AA30)/AA30 -> 0.011933965 | AT30: =AW30 + ABS(AU30) + ABS(AV30) -> 0 | BA30: FALSE | BB30: FALSE | BC30: =(AX30-AM30)/AM30 -> -1 | BD30: =(AW30-AL30)/AL30 -> -1 | BE30: =BH30 + ABS(BF30) + ABS(BG30) -> 0 | BL30: FALSE | BM30: FALSE | BN30: =(BI30-AZ30)/AZ30 -> #DIV/0! | BO30: =(BH30-AW30)/AW30 -> #DIV/0! | BP30: =BS30 + ABS(BQ30) + ABS(BR30) -> 0 | BW30: FALSE | BX30: FALSE | BY30: =(BT30-BI30)/BI30 -> #DIV/0! | BZ30: =(BS30-BH30)/BH30 -> #DIV/0! | CA30: =CD30 + ABS(CB30) + ABS(CC30) -> 0 | CH30: FALSE | CI30: FALSE | CJ30: =(CE30-BV30)/BV30 -> #DIV/0! | CK30: =(CD30-BS30)/BS30 -> #DIV/0! | CL30: =CO30 + ABS(CM30) + ABS(CN30) -> 0 | CS30: FALSE | CT30: FALSE | CU30: =(CP30-CE30)/CE30 -> #DIV/0! | CV30: =(CO30-CD30)/CD30 -> #DIV/0! | CW30: =CZ30 + ABS(CX30) + ABS(CY30) -> 0 | DD30: FALSE | DE30: FALSE | DF30: =(DA30-CR30)/CR30 -> #DIV/0! | DG30: =(CZ30-CO30)/CO30 -> #DIV/0! | DH30: =DK30 + ABS(DI30) + ABS(DJ30) -> 0 | DO30: FALSE | DP30: FALSE | DQ30: =(DL30-DA30)/DA30 -> #DIV/0! | DR30: =(DK30-CZ30)/CZ30 -> #DIV/0! | DS30: =DV30 + ABS(DT30) + ABS(DU30) -> 0 | DZ30: FALSE | EA30: FALSE | EB30: =(DW30-DN30)/DN30 -> #DIV/0! | EC30: =(DV30-DK30)/DK30 -> #DIV/0! | ED30: =EG30 + ABS(EE30) + ABS(EF30) -> 0 | EK30: FALSE | EL30: FALSE | EM30: =(EH30-DW30)/DW30 -> #DIV/0! | EN30: =(EG30-DV30)/DV30 -> #DIV/0! | EO30: =ER30 + ABS(EP30) + ABS(EQ30) -> 0 | EV30: FALSE | EW30: FALSE | EX30: =(ES30-EJ30)/EJ30 -> #DIV/0! | EY30: =(ER30-EG30)/EG30 -> #DIV/0!
C31: PENITENCIÁRIA JOSÉ MARIA ALKIMIM | D31: 1450022 | E31: 35 | F31: Y23G1222172 | G31: 00106360779 | H31: COMPANHIA DE SANEAMENTO DE MINAS GERAIS COPASA MG | I31: 17.281.106/0001-03 | N31: 107 | P31: 2.6 | R31: 51.52 | T31: 1450.01.0005511/2026-51 | X31: =AA31 + ABS(Y31) + ABS(Z31) -> 242.67 | Y31: -11.65 | Z31: 0 | AA31: 231.02 | AB31: 15 | AC31: 10/03/2026 | AD31: 1450.01.0029372/2026-78 | AE31: TRUE | AF31: TRUE | AG31: 0 | AH31: =(AA31-R31)/R31 -> 3.4840839 | AI31: =AL31 + ABS(AJ31) + ABS(AK31) -> 618.48 | AJ31: -29.69 | AK31: 0 | AL31: 588.79 | AM31: 32 | AN31: 46122 | AO31: 1450.01.0046622/2026-25 | AP31: TRUE | AQ31: TRUE | AR31: =(AM31-AB31)/AB31 -> 1.1333333 | AS31: =(AL31-AA31)/AA31 -> 1.5486538 | AT31: =AW31 + ABS(AU31) + ABS(AV31) -> 0 | BA31: FALSE | BB31: FALSE | BC31: =(AX31-AM31)/AM31 -> -1 | BD31: =(AW31-AL31)/AL31 -> -1 | BE31: =BH31 + ABS(BF31) + ABS(BG31) -> 0 | BL31: FALSE | BM31: FALSE | BN31: =(BI31-AZ31)/AZ31 -> #DIV/0! | BO31: =(BH31-AW31)/AW31 -> #DIV/0! | BP31: =BS31 + ABS(BQ31) + ABS(BR31) -> 0 | BW31: FALSE | BX31: FALSE | BY31: =(BT31-BI31)/BI31 -> #DIV/0! | BZ31: =(BS31-BH31)/BH31 -> #DIV/0! | CA31: =CD31 + ABS(CB31) + ABS(CC31) -> 0 | CH31: FALSE | CI31: FALSE | CJ31: =(CE31-BV31)/BV31 -> #DIV/0! | CK31: =(CD31-BS31)/BS31 -> #DIV/0! | CL31: =CO31 + ABS(CM31) + ABS(CN31) -> 0 | CS31: FALSE | CT31: FALSE | CU31: =(CP31-CE31)/CE31 -> #DIV/0! | CV31: =(CO31-CD31)/CD31 -> #DIV/0! | CW31: =CZ31 + ABS(CX31) + ABS(CY31) -> 0 | DD31: FALSE | DE31: FALSE | DF31: =(DA31-CR31)/CR31 -> #DIV/0! | DG31: =(CZ31-CO31)/CO31 -> #DIV/0! | DH31: =DK31 + ABS(DI31) + ABS(DJ31) -> 0 | DO31: FALSE | DP31: FALSE | DQ31: =(DL31-DA31)/DA31 -> #DIV/0! | DR31: =(DK31-CZ31)/CZ31 -> #DIV/0! | DS31: =DV31 + ABS(DT31) + ABS(DU31) -> 0 | DZ31: FALSE | EA31: FALSE | EB31: =(DW31-DN31)/DN31 -> #DIV/0! | EC31: =(DV31-DK31)/DK31 -> #DIV/0! | ED31: =EG31 + ABS(EE31) + ABS(EF31) -> 0 | EK31: FALSE | EL31: FALSE | EM31: =(EH31-DW31)/DW31 -> #DIV/0! | EN31: =(EG31-DV31)/DV31 -> #DIV/0! | EO31: =ER31 + ABS(EP31) + ABS(EQ31) -> 0 | EV31: FALSE | EW31: FALSE | EX31: =(ES31-EJ31)/EJ31 -> #DIV/0! | EY31: =(ER31-EG31)/EG31 -> #DIV/0!
C32: PENITENCIÁRIA JOSÉ MARIA ALKIMIM | D32: 1450022 | E32: 35 | F32: Y24F0430859 | G32: 00106359029 | H32: COMPANHIA DE SANEAMENTO DE MINAS GERAIS COPASA MG | I32: 17.281.106/0001-03 | N32: 107 | P32: 15.69 | R32: 311.2 | S32: 20 | T32: 1450.01.0005511/2026-51 | X32: =AA32 + ABS(Y32) + ABS(Z32) -> 293.2 | Y32: -14.07 | Z32: 0 | AA32: 279.13 | AB32: 18 | AC32: 10/03/2026 | AD32: 1450.01.0029372/2026-78 | AE32: TRUE | AF32: TRUE | AG32: =(AB32-S32)/S32 -> -0.1 | AH32: =(AA32-R32)/R32 -> -0.1030527 | AI32: =AL32 + ABS(AJ32) + ABS(AK32) -> 226.75 | AJ32: -10.88 | AK32: 0 | AL32: 215.87 | AM32: 13 | AN32: 46122 | AO32: 1450.01.0046622/2026-25 | AP32: TRUE | AQ32: TRUE | AR32: =(AM32-AB32)/AB32 -> -0.27777778 | AS32: =(AL32-AA32)/AA32 -> -0.22663275 | AT32: =AW32 + ABS(AU32) + ABS(AV32) -> 0 | BA32: FALSE | BB32: FALSE | BC32: =(AX32-AM32)/AM32 -> -1 | BD32: =(AW32-AL32)/AL32 -> -1 | BE32: =BH32 + ABS(BF32) + ABS(BG32) -> 0 | BL32: FALSE | BM32: FALSE | BN32: =(BI32-AZ32)/AZ32 -> #DIV/0! | BO32: =(BH32-AW32)/AW32 -> #DIV/0! | BP32: =BS32 + ABS(BQ32) + ABS(BR32) -> 0 | BW32: FALSE | BX32: FALSE | BY32: =(BT32-BI32)/BI32 -> #DIV/0! | BZ32: =(BS32-BH32)/BH32 -> #DIV/0! | CA32: =CD32 + ABS(CB32) + ABS(CC32) -> 0 | CH32: FALSE | CI32: FALSE | CJ32: =(CE32-BV32)/BV32 -> #DIV/0! | CK32: =(CD32-BS32)/BS32 -> #DIV/0! | CL32: =CO32 + ABS(CM32) + ABS(CN32) -> 0 | CS32: FALSE | CT32: FALSE | CU32: =(CP32-CE32)/CE32 -> #DIV/0! | CV32: =(CO32-CD32)/CD32 -> #DIV/0! | CW32: =CZ32 + ABS(CX32) + ABS(CY32) -> 0 | DD32: FALSE | DE32: FALSE | DF32: =(DA32-CR32)/CR32 -> #DIV/0! | DG32: =(CZ32-CO32)/CO32 -> #DIV/0! | DH32: =DK32 + ABS(DI32) + ABS(DJ32) -> 0 | DO32: FALSE | DP32: FALSE | DQ32: =(DL32-DA32)/DA32 -> #DIV/0! | DR32: =(DK32-CZ32)/CZ32 -> #DIV/0! | DS32: =DV32 + ABS(DT32) + ABS(DU32) -> 0 | DZ32: FALSE | EA32: FALSE | EB32: =(DW32-DN32)/DN32 -> #DIV/0! | EC32: =(DV32-DK32)/DK32 -> #DIV/0! | ED32: =EG32 + ABS(EE32) + ABS(EF32) -> 0 | EK32: FALSE | EL32: FALSE | EM32: =(EH32-DW32)/DW32 -> #DIV/0! | EN32: =(EG32-DV32)/DV32 -> #DIV/0! | EO32: =ER32 + ABS(EP32) + ABS(EQ32) -> 0 | EV32: FALSE | EW32: FALSE | EX32: =(ES32-EJ32)/EJ32 -> #DIV/0! | EY32: =(ER32-EG32)/EG32 -> #DIV/0!
C33: PENITENCIÁRIA JOSÉ MARIA ALKIMIM | D33: 1450022 | E33: 35 | F33: A24H0025317 | G33: 00106357140 | H33: COMPANHIA DE SANEAMENTO DE MINAS GERAIS COPASA MG | I33: 17.281.106/0001-03 | N33: 107 | P33: 24.86 | R33: 493.08 | S33: 29 | T33: 1450.01.0005511/2026-51 | X33: =AA33 + ABS(Y33) + ABS(Z33) -> 1111.67 | Y33: -53.36 | Z33: 0 | AA33: 1058.31 | AB33: 54 | AC33: 10/03/2026 | AD33: 1450.01.0029372/2026-78 | AE33: TRUE | AF33: TRUE | AG33: =(AB33-S33)/S33 -> 0.86206897 | AH33: =(AA33-R33)/R33 -> 1.1463251 | AI33: =AL33 + ABS(AJ33) + ABS(AK33) -> 931.83 | AJ33: -44.73 | AK33: 0 | AL33: 887.1 | AM33: 45 | AN33: 46122 | AO33: 1450.01.0046622/2026-25 | AP33: TRUE | AQ33: TRUE | AR33: =(AM33-AB33)/AB33 -> -0.16666667 | AS33: =(AL33-AA33)/AA33 -> -0.1617768 | AT33: =AW33 + ABS(AU33) + ABS(AV33) -> 0 | BA33: FALSE | BB33: FALSE | BC33: =(AX33-AM33)/AM33 -> -1 | BD33: =(AW33-AL33)/AL33 -> -1 | BE33: =BH33 + ABS(BF33) + ABS(BG33) -> 0 | BL33: FALSE | BM33: FALSE | BN33: =(BI33-AZ33)/AZ33 -> #DIV/0! | BO33: =(BH33-AW33)/AW33 -> #DIV/0! | BP33: =BS33 + ABS(BQ33) + ABS(BR33) -> 0 | BW33: FALSE | BX33: FALSE | BY33: =(BT33-BI33)/BI33 -> #DIV/0! | BZ33: =(BS33-BH33)/BH33 -> #DIV/0! | CA33: =CD33 + ABS(CB33) + ABS(CC33) -> 0 | CH33: FALSE | CI33: FALSE | CJ33: =(CE33-BV33)/BV33 -> #DIV/0! | CK33: =(CD33-BS33)/BS33 -> #DIV/0! | CL33: =CO33 + ABS(CM33) + ABS(CN33) -> 0 | CS33: FALSE | CT33: FALSE | CU33: =(CP33-CE33)/CE33 -> #DIV/0! | CV33: =(CO33-CD33)/CD33 -> #DIV/0! | CW33: =CZ33 + ABS(CX33) + ABS(CY33) -> 0 | DD33: FALSE | DE33: FALSE | DF33: =(DA33-CR33)/CR33 -> #DIV/0! | DG33: =(CZ33-CO33)/CO33 -> #DIV/0! | DH33: =DK33 + ABS(DI33) + ABS(DJ33) -> 0 | DO33: FALSE | DP33: FALSE | DQ33: =(DL33-DA33)/DA33 -> #DIV/0! | DR33: =(DK33-CZ33)/CZ33 -> #DIV/0! | DS33: =DV33 + ABS(DT33) + ABS(DU33) -> 0 | DZ33: FALSE | EA33: FALSE | EB33: =(DW33-DN33)/DN33 -> #DIV/0! | EC33: =(DV33-DK33)/DK33 -> #DIV/0! | ED33: =EG33 + ABS(EE33) + ABS(EF33) -> 0 | EK33: FALSE | EL33: FALSE | EM33: =(EH33-DW33)/DW33 -> #DIV/0! | EN33: =(EG33-DV33)/DV33 -> #DIV/0! | EO33: =ER33 + ABS(EP33) + ABS(EQ33) -> 0 | EV33: FALSE | EW33: FALSE | EX33: =(ES33-EJ33)/EJ33 -> #DIV/0! | EY33: =(ER33-EG33)/EG33 -> #DIV/0!
C34: PENITENCIÁRIA JOSÉ MARIA ALKIMIM | D34: 1450022 | E34: 35 | F34: Y24S1242222 | G34: 00106356950 | H34: COMPANHIA DE SANEAMENTO DE MINAS GERAIS COPASA MG | I34: 17.281.106/0001-03 | N34: 107 | P34: 30.97 | R34: 614.34 | S34: 35 | T34: 1450.01.0005511/2026-51 | X34: =AA34 + ABS(Y34) + ABS(Z34) -> 276.36 | Y34: -13.27 | Z34: 0 | AA34: 263.09 | AB34: 17 | AC34: 10/03/2026 | AD34: 1450.01.0029372/2026-78 | AE34: TRUE | AF34: TRUE | AG34: =(AB34-S34)/S34 -> -0.51428571 | AH34: =(AA34-R34)/R34 -> -0.5717518 | AI34: =AL34 + ABS(AJ34) + ABS(AK34) -> 262.21 | AJ34: -12.59 | AK34: 0 | AL34: 249.62 | AM34: 15 | AN34: 46122 | AO34: 1450.01.0046622/2026-25 | AP34: TRUE | AQ34: TRUE | AR34: =(AM34-AB34)/AB34 -> -0.11764706 | AS34: =(AL34-AA34)/AA34 -> -0.051199209 | AT34: =AW34 + ABS(AU34) + ABS(AV34) -> 0 | BA34: FALSE | BB34: FALSE | BC34: =(AX34-AM34)/AM34 -> -1 | BD34: =(AW34-AL34)/AL34 -> -1 | BE34: =BH34 + ABS(BF34) + ABS(BG34) -> 0 | BL34: FALSE | BM34: FALSE | BN34: =(BI34-AZ34)/AZ34 -> #DIV/0! | BO34: =(BH34-AW34)/AW34 -> #DIV/0! | BP34: =BS34 + ABS(BQ34) + ABS(BR34) -> 0 | BW34: FALSE | BX34: FALSE | BY34: =(BT34-BI34)/BI34 -> #DIV/0! | BZ34: =(BS34-BH34)/BH34 -> #DIV/0! | CA34: =CD34 + ABS(CB34) + ABS(CC34) -> 0 | CH34: FALSE | CI34: FALSE | CJ34: =(CE34-BV34)/BV34 -> #DIV/0! | CK34: =(CD34-BS34)/BS34 -> #DIV/0! | CL34: =CO34 + ABS(CM34) + ABS(CN34) -> 0 | CS34: FALSE | CT34: FALSE | CU34: =(CP34-CE34)/CE34 -> #DIV/0! | CV34: =(CO34-CD34)/CD34 -> #DIV/0! | CW34: =CZ34 + ABS(CX34) + ABS(CY34) -> 0 | DD34: FALSE | DE34: FALSE | DF34: =(DA34-CR34)/CR34 -> #DIV/0! | DG34: =(CZ34-CO34)/CO34 -> #DIV/0! | DH34: =DK34 + ABS(DI34) + ABS(DJ34) -> 0 | DO34: FALSE | DP34: FALSE | DQ34: =(DL34-DA34)/DA34 -> #DIV/0! | DR34: =(DK34-CZ34)/CZ34 -> #DIV/0! | DS34: =DV34 + ABS(DT34) + ABS(DU34) -> 0 | DZ34: FALSE | EA34: FALSE | EB34: =(DW34-DN34)/DN34 -> #DIV/0! | EC34: =(DV34-DK34)/DK34 -> #DIV/0! | ED34: =EG34 + ABS(EE34) + ABS(EF34) -> 0 | EK34: FALSE | EL34: FALSE | EM34: =(EH34-DW34)/DW34 -> #DIV/0! | EN34: =(EG34-DV34)/DV34 -> #DIV/0! | EO34: =ER34 + ABS(EP34) + ABS(EQ34) -> 0 | EV34: FALSE | EW34: FALSE | EX34: =(ES34-EJ34)/EJ34 -> #DIV/0! | EY34: =(ER34-EG34)/EG34 -> #DIV/0!
C35: PENITENCIÁRIA JOSÉ MARIA ALKIMIM | D35: 1450022 | E35: 35 | F35: Y20G0674247 | G35: 00106359878 | H35: COMPANHIA DE SANEAMENTO DE MINAS GERAIS COPASA MG | I35: 17.281.106/0001-03 | N35: 107 | P35: 9.22 | R35: 182.91 | S35: 12 | T35: 1450.01.0005511/2026-51 | X35: =AA35 + ABS(Y35) + ABS(Z35) -> 242.67 | Y35: -11.65 | Z35: 0 | AA35: 231.02 | AB35: 15 | AC35: 10/03/2026 | AD35: 1450.01.0029372/2026-78 | AE35: TRUE | AF35: TRUE | AG35: =(AB35-S35)/S35 -> 0.25 | AH35: =(AA35-R35)/R35 -> 0.26302553 | AI35: =AL35 + ABS(AJ35) + ABS(AK35) -> 279.94 | AJ35: -13.44 | AK35: 0 | AL35: 266.5 | AM35: 16 | AN35: 46122 | AO35: 1450.01.0046622/2026-25 | AP35: TRUE | AQ35: TRUE | AR35: =(AM35-AB35)/AB35 -> 0.066666667 | AS35: =(AL35-AA35)/AA35 -> 0.15357978 | AT35: =AW35 + ABS(AU35) + ABS(AV35) -> 0 | BA35: FALSE | BB35: FALSE | BC35: =(AX35-AM35)/AM35 -> -1 | BD35: =(AW35-AL35)/AL35 -> -1 | BE35: =BH35 + ABS(BF35) + ABS(BG35) -> 0 | BL35: FALSE | BM35: FALSE | BN35: =(BI35-AZ35)/AZ35 -> #DIV/0! | BO35: =(BH35-AW35)/AW35 -> #DIV/0! | BP35: =BS35 + ABS(BQ35) + ABS(BR35) -> 0 | BW35: FALSE | BX35: FALSE | BY35: =(BT35-BI35)/BI35 -> #DIV/0! | BZ35: =(BS35-BH35)/BH35 -> #DIV/0! | CA35: =CD35 + ABS(CB35) + ABS(CC35) -> 0 | CH35: FALSE | CI35: FALSE | CJ35: =(CE35-BV35)/BV35 -> #DIV/0! | CK35: =(CD35-BS35)/BS35 -> #DIV/0! | CL35: =CO35 + ABS(CM35) + ABS(CN35) -> 0 | CS35: FALSE | CT35: FALSE | CU35: =(CP35-CE35)/CE35 -> #DIV/0! | CV35: =(CO35-CD35)/CD35 -> #DIV/0! | CW35: =CZ35 + ABS(CX35) + ABS(CY35) -> 0 | DD35: FALSE | DE35: FALSE | DF35: =(DA35-CR35)/CR35 -> #DIV/0! | DG35: =(CZ35-CO35)/CO35 -> #DIV/0! | DH35: =DK35 + ABS(DI35) + ABS(DJ35) -> 0 | DO35: FALSE | DP35: FALSE | DQ35: =(DL35-DA35)/DA35 -> #DIV/0! | DR35: =(DK35-CZ35)/CZ35 -> #DIV/0! | DS35: =DV35 + ABS(DT35) + ABS(DU35) -> 0 | DZ35: FALSE | EA35: FALSE | EB35: =(DW35-DN35)/DN35 -> #DIV/0! | EC35: =(DV35-DK35)/DK35 -> #DIV/0! | ED35: =EG35 + ABS(EE35) + ABS(EF35) -> 0 | EK35: FALSE | EL35: FALSE | EM35: =(EH35-DW35)/DW35 -> #DIV/0! | EN35: =(EG35-DV35)/DV35 -> #DIV/0! | EO35: =ER35 + ABS(EP35) + ABS(EQ35) -> 0 | EV35: FALSE | EW35: FALSE | EX35: =(ES35-EJ35)/EJ35 -> #DIV/0! | EY35: =(ER35-EG35)/EG35 -> #DIV/0!
C36: PENITENCIÁRIA JOSÉ MARIA ALKIMIM | D36: 1450022 | E36: 35 | F36: Y21S0634297 | G36: 00106360744 | H36: COMPANHIA DE SANEAMENTO DE MINAS GERAIS COPASA MG | I36: 17.281.106/0001-03 | N36: 107 | P36: 4.2 | R36: 83.28 | S36: 4 | T36: 1450.01.0005511/2026-51 | X36: =AA36 + ABS(Y36) + ABS(Z36) -> 242.67 | Y36: -11.65 | Z36: 0 | AA36: 231.02 | AB36: 15 | AC36: 10/03/2026 | AD36: 1450.01.0029372/2026-78 | AE36: TRUE | AF36: TRUE | AG36: =(AB36-S36)/S36 -> 2.75 | AH36: =(AA36-R36)/R36 -> 1.7740154 | AI36: =AL36 + ABS(AJ36) + ABS(AK36) -> 191.29 | AJ36: -9.18 | AK36: 0 | AL36: 182.11 | AM36: 11 | AN36: 46122 | AO36: 1450.01.0046622/2026-25 | AP36: TRUE | AQ36: TRUE | AR36: =(AM36-AB36)/AB36 -> -0.26666667 | AS36: =(AL36-AA36)/AA36 -> -0.21171327 | AT36: =AW36 + ABS(AU36) + ABS(AV36) -> 0 | BA36: FALSE | BB36: FALSE | BC36: =(AX36-AM36)/AM36 -> -1 | BD36: =(AW36-AL36)/AL36 -> -1 | BE36: =BH36 + ABS(BF36) + ABS(BG36) -> 0 | BL36: FALSE | BM36: FALSE | BN36: =(BI36-AZ36)/AZ36 -> #DIV/0! | BO36: =(BH36-AW36)/AW36 -> #DIV/0! | BP36: =BS36 + ABS(BQ36) + ABS(BR36) -> 0 | BW36: FALSE | BX36: FALSE | BY36: =(BT36-BI36)/BI36 -> #DIV/0! | BZ36: =(BS36-BH36)/BH36 -> #DIV/0! | CA36: =CD36 + ABS(CB36) + ABS(CC36) -> 0 | CH36: FALSE | CI36: FALSE | CJ36: =(CE36-BV36)/BV36 -> #DIV/0! | CK36: =(CD36-BS36)/BS36 -> #DIV/0! | CL36: =CO36 + ABS(CM36) + ABS(CN36) -> 0 | CS36: FALSE | CT36: FALSE | CU36: =(CP36-CE36)/CE36 -> #DIV/0! | CV36: =(CO36-CD36)/CD36 -> #DIV/0! | CW36: =CZ36 + ABS(CX36) + ABS(CY36) -> 0 | DD36: FALSE | DE36: FALSE | DF36: =(DA36-CR36)/CR36 -> #DIV/0! | DG36: =(CZ36-CO36)/CO36 -> #DIV/0! | DH36: =DK36 + ABS(DI36) + ABS(DJ36) -> 0 | DO36: FALSE | DP36: FALSE | DQ36: =(DL36-DA36)/DA36 -> #DIV/0! | DR36: =(DK36-CZ36)/CZ36 -> #DIV/0! | DS36: =DV36 + ABS(DT36) + ABS(DU36) -> 0 | DZ36: FALSE | EA36: FALSE | EB36: =(DW36-DN36)/DN36 -> #DIV/0! | EC36: =(DV36-DK36)/DK36 -> #DIV/0! | ED36: =EG36 + ABS(EE36) + ABS(EF36) -> 0 | EK36: FALSE | EL36: FALSE | EM36: =(EH36-DW36)/DW36 -> #DIV/0! | EN36: =(EG36-DV36)/DV36 -> #DIV/0! | EO36: =ER36 + ABS(EP36) + ABS(EQ36) -> 0 | EV36: FALSE | EW36: FALSE | EX36: =(ES36-EJ36)/EJ36 -> #DIV/0! | EY36: =(ER36-EG36)/EG36 -> #DIV/0!
C37: PENITENCIÁRIA JOSÉ MARIA ALKIMIM | D37: 1450022 | E37: 35 | F37: Y23G1129610 | G37: 00106360884 | H37: COMPANHIA DE SANEAMENTO DE MINAS GERAIS COPASA MG | I37: 17.281.106/0001-03 | N37: 107 | P37: 3 | R37: 59.46 | S37: 1 | T37: 1450.01.0005511/2026-51 | X37: =AA37 + ABS(Y37) + ABS(Z37) -> 54.12 | Y37: -2.6 | Z37: 0 | AA37: 51.52 | AB37: 0 | AC37: 10/03/2026 | AD37: 1450.01.0029372/2026-78 | AE37: TRUE | AF37: TRUE | AG37: =(AB37-S37)/S37 -> -1 | AH37: =(AA37-R37)/R37 -> -0.13353515 | AI37: =AL37 + ABS(AJ37) + ABS(AK37) -> 63.39 | AJ37: -3.04 | AK37: 0 | AL37: 60.35 | AM37: 0 | AN37: 46122 | AO37: 1450.01.0046622/2026-25 | AP37: TRUE | AQ37: TRUE | AR37: 0 | AS37: =(AL37-AA37)/AA37 -> 0.17138975 | AT37: =AW37 + ABS(AU37) + ABS(AV37) -> 0 | BA37: FALSE | BB37: FALSE | BC37: =(AX37-AM37)/AM37 -> #DIV/0! | BD37: =(AW37-AL37)/AL37 -> -1 | BE37: =BH37 + ABS(BF37) + ABS(BG37) -> 0 | BL37: FALSE | BM37: FALSE | BN37: =(BI37-AZ37)/AZ37 -> #DIV/0! | BO37: =(BH37-AW37)/AW37 -> #DIV/0! | BP37: =BS37 + ABS(BQ37) + ABS(BR37) -> 0 | BW37: FALSE | BX37: FALSE | BY37: =(BT37-BI37)/BI37 -> #DIV/0! | BZ37: =(BS37-BH37)/BH37 -> #DIV/0! | CA37: =CD37 + ABS(CB37) + ABS(CC37) -> 0 | CH37: FALSE | CI37: FALSE | CJ37: =(CE37-BV37)/BV37 -> #DIV/0! | CK37: =(CD37-BS37)/BS37 -> #DIV/0! | CL37: =CO37 + ABS(CM37) + ABS(CN37) -> 0 | CS37: FALSE | CT37: FALSE | CU37: =(CP37-CE37)/CE37 -> #DIV/0! | CV37: =(CO37-CD37)/CD37 -> #DIV/0! | CW37: =CZ37 + ABS(CX37) + ABS(CY37) -> 0 | DD37: FALSE | DE37: FALSE | DF37: =(DA37-CR37)/CR37 -> #DIV/0! | DG37: =(CZ37-CO37)/CO37 -> #DIV/0! | DH37: =DK37 + ABS(DI37) + ABS(DJ37) -> 0 | DO37: FALSE | DP37: FALSE | DQ37: =(DL37-DA37)/DA37 -> #DIV/0! | DR37: =(DK37-CZ37)/CZ37 -> #DIV/0! | DS37: =DV37 + ABS(DT37) + ABS(DU37) -> 0 | DZ37: FALSE | EA37: FALSE | EB37: =(DW37-DN37)/DN37 -> #DIV/0! | EC37: =(DV37-DK37)/DK37 -> #DIV/0! | ED37: =EG37 + ABS(EE37) + ABS(EF37) -> 0 | EK37: FALSE | EL37: FALSE | EM37: =(EH37-DW37)/DW37 -> #DIV/0! | EN37: =(EG37-DV37)/DV37 -> #DIV/0! | EO37: =ER37 + ABS(EP37) + ABS(EQ37) -> 0 | EV37: FALSE | EW37: FALSE | EX37: =(ES37-EJ37)/EJ37 -> #DIV/0! | EY37: =(ER37-EG37)/EG37 -> #DIV/0!
C38: PENITENCIÁRIA JOSÉ MARIA ALKIMIM | D38: 1450022 | E38: 35 | F38: A24H0001971 | G38: 00106359614 | H38: COMPANHIA DE SANEAMENTO DE MINAS GERAIS COPASA MG | I38: 17.281.106/0001-03 | N38: 107 | P38: 27.92 | R38: 553.71 | S38: 32 | T38: 1450.01.0005511/2026-51 | X38: =AA38 + ABS(Y38) + ABS(Z38) -> 242.67 | Y38: -11.65 | Z38: 0 | AA38: 231.02 | AB38: 15 | AC38: 10/03/2026 | AD38: 1450.01.0029372/2026-78 | AE38: TRUE | AF38: TRUE | AG38: =(AB38-S38)/S38 -> -0.53125 | AH38: =(AA38-R38)/R38 -> -0.58277799 | AI38: =AL38 + ABS(AJ38) + ABS(AK38) -> 147.11 | AJ38: -7.06 | AK38: 0 | AL38: 140.05 | AM38: 8 | AN38: 46122 | AO38: 1450.01.0046622/2026-25 | AP38: TRUE | AQ38: TRUE | AR38: =(AM38-AB38)/AB38 -> -0.46666667 | AS38: =(AL38-AA38)/AA38 -> -0.39377543 | AT38: =AW38 + ABS(AU38) + ABS(AV38) -> 0 | BA38: FALSE | BB38: FALSE | BC38: =(AX38-AM38)/AM38 -> -1 | BD38: =(AW38-AL38)/AL38 -> -1 | BE38: =BH38 + ABS(BF38) + ABS(BG38) -> 0 | BL38: FALSE | BM38: FALSE | BN38: =(BI38-AZ38)/AZ38 -> #DIV/0! | BO38: =(BH38-AW38)/AW38 -> #DIV/0! | BP38: =BS38 + ABS(BQ38) + ABS(BR38) -> 0 | BW38: FALSE | BX38: FALSE | BY38: =(BT38-BI38)/BI38 -> #DIV/0! | BZ38: =(BS38-BH38)/BH38 -> #DIV/0! | CA38: =CD38 + ABS(CB38) + ABS(CC38) -> 0 | CH38: FALSE | CI38: FALSE | CJ38: =(CE38-BV38)/BV38 -> #DIV/0! | CK38: =(CD38-BS38)/BS38 -> #DIV/0! | CL38: =CO38 + ABS(CM38) + ABS(CN38) -> 0 | CS38: FALSE | CT38: FALSE | CU38: =(CP38-CE38)/CE38 -> #DIV/0! | CV38: =(CO38-CD38)/CD38 -> #DIV/0! | CW38: =CZ38 + ABS(CX38) + ABS(CY38) -> 0 | DD38: FALSE | DE38: FALSE | DF38: =(DA38-CR38)/CR38 -> #DIV/0! | DG38: =(CZ38-CO38)/CO38 -> #DIV/0! | DH38: =DK38 + ABS(DI38) + ABS(DJ38) -> 0 | DO38: FALSE | DP38: FALSE | DQ38: =(DL38-DA38)/DA38 -> #DIV/0! | DR38: =(DK38-CZ38)/CZ38 -> #DIV/0! | DS38: =DV38 + ABS(DT38) + ABS(DU38) -> 0 | DZ38: FALSE | EA38: FALSE | EB38: =(DW38-DN38)/DN38 -> #DIV/0! | EC38: =(DV38-DK38)/DK38 -> #DIV/0! | ED38: =EG38 + ABS(EE38) + ABS(EF38) -> 0 | EK38: FALSE | EL38: FALSE | EM38: =(EH38-DW38)/DW38 -> #DIV/0! | EN38: =(EG38-DV38)/DV38 -> #DIV/0! | EO38: =ER38 + ABS(EP38) + ABS(EQ38) -> 0 | EV38: FALSE | EW38: FALSE | EX38: =(ES38-EJ38)/EJ38 -> #DIV/0! | EY38: =(ER38-EG38)/EG38 -> #DIV/0!
